{
  "nbformat": 4,
  "nbformat_minor": 0,
  "metadata": {
    "colab": {
      "name": "Image_Classification_webapp.ipynb",
      "provenance": [],
      "collapsed_sections": [],
      "mount_file_id": "1HYJk3Z3XbWXOPe2pAQsmjHN82rBbuYGs",
      "authorship_tag": "ABX9TyO2CanMWvsCWqcbqS9nSm8E",
      "include_colab_link": true
    },
    "kernelspec": {
      "name": "python3",
      "display_name": "Python 3"
    },
    "language_info": {
      "name": "python"
    }
  },
  "cells": [
    {
      "cell_type": "markdown",
      "metadata": {
        "id": "view-in-github",
        "colab_type": "text"
      },
      "source": [
        "<a href=\"https://colab.research.google.com/github/Sagar-modelling/Fire_Fighting/blob/main/Image_Classification_webapp.ipynb\" target=\"_parent\"><img src=\"https://colab.research.google.com/assets/colab-badge.svg\" alt=\"Open In Colab\"/></a>"
      ]
    },
    {
      "cell_type": "code",
      "metadata": {
        "colab": {
          "base_uri": "https://localhost:8080/"
        },
        "id": "vv2kMx_bOwXA",
        "outputId": "babcc5cc-aa27-4c76-9ec7-c0c6c272a8b5"
      },
      "source": [
        "!pip install tensorflow"
      ],
      "execution_count": null,
      "outputs": [
        {
          "output_type": "stream",
          "name": "stdout",
          "text": [
            "Requirement already satisfied: tensorflow in /usr/local/lib/python3.7/dist-packages (2.6.0)\n",
            "Requirement already satisfied: flatbuffers~=1.12.0 in /usr/local/lib/python3.7/dist-packages (from tensorflow) (1.12)\n",
            "Requirement already satisfied: keras~=2.6 in /usr/local/lib/python3.7/dist-packages (from tensorflow) (2.6.0)\n",
            "Requirement already satisfied: termcolor~=1.1.0 in /usr/local/lib/python3.7/dist-packages (from tensorflow) (1.1.0)\n",
            "Requirement already satisfied: protobuf>=3.9.2 in /usr/local/lib/python3.7/dist-packages (from tensorflow) (3.17.3)\n",
            "Requirement already satisfied: six~=1.15.0 in /usr/local/lib/python3.7/dist-packages (from tensorflow) (1.15.0)\n",
            "Requirement already satisfied: keras-preprocessing~=1.1.2 in /usr/local/lib/python3.7/dist-packages (from tensorflow) (1.1.2)\n",
            "Requirement already satisfied: tensorflow-estimator~=2.6 in /usr/local/lib/python3.7/dist-packages (from tensorflow) (2.6.0)\n",
            "Requirement already satisfied: typing-extensions~=3.7.4 in /usr/local/lib/python3.7/dist-packages (from tensorflow) (3.7.4.3)\n",
            "Requirement already satisfied: grpcio<2.0,>=1.37.0 in /usr/local/lib/python3.7/dist-packages (from tensorflow) (1.41.0)\n",
            "Requirement already satisfied: google-pasta~=0.2 in /usr/local/lib/python3.7/dist-packages (from tensorflow) (0.2.0)\n",
            "Requirement already satisfied: numpy~=1.19.2 in /usr/local/lib/python3.7/dist-packages (from tensorflow) (1.19.5)\n",
            "Requirement already satisfied: clang~=5.0 in /usr/local/lib/python3.7/dist-packages (from tensorflow) (5.0)\n",
            "Requirement already satisfied: absl-py~=0.10 in /usr/local/lib/python3.7/dist-packages (from tensorflow) (0.12.0)\n",
            "Requirement already satisfied: tensorboard~=2.6 in /usr/local/lib/python3.7/dist-packages (from tensorflow) (2.6.0)\n",
            "Requirement already satisfied: wrapt~=1.12.1 in /usr/local/lib/python3.7/dist-packages (from tensorflow) (1.12.1)\n",
            "Requirement already satisfied: h5py~=3.1.0 in /usr/local/lib/python3.7/dist-packages (from tensorflow) (3.1.0)\n",
            "Requirement already satisfied: astunparse~=1.6.3 in /usr/local/lib/python3.7/dist-packages (from tensorflow) (1.6.3)\n",
            "Requirement already satisfied: gast==0.4.0 in /usr/local/lib/python3.7/dist-packages (from tensorflow) (0.4.0)\n",
            "Requirement already satisfied: opt-einsum~=3.3.0 in /usr/local/lib/python3.7/dist-packages (from tensorflow) (3.3.0)\n",
            "Requirement already satisfied: wheel~=0.35 in /usr/local/lib/python3.7/dist-packages (from tensorflow) (0.37.0)\n",
            "Requirement already satisfied: cached-property in /usr/local/lib/python3.7/dist-packages (from h5py~=3.1.0->tensorflow) (1.5.2)\n",
            "Requirement already satisfied: tensorboard-plugin-wit>=1.6.0 in /usr/local/lib/python3.7/dist-packages (from tensorboard~=2.6->tensorflow) (1.8.0)\n",
            "Requirement already satisfied: tensorboard-data-server<0.7.0,>=0.6.0 in /usr/local/lib/python3.7/dist-packages (from tensorboard~=2.6->tensorflow) (0.6.1)\n",
            "Requirement already satisfied: setuptools>=41.0.0 in /usr/local/lib/python3.7/dist-packages (from tensorboard~=2.6->tensorflow) (57.4.0)\n",
            "Requirement already satisfied: google-auth-oauthlib<0.5,>=0.4.1 in /usr/local/lib/python3.7/dist-packages (from tensorboard~=2.6->tensorflow) (0.4.6)\n",
            "Requirement already satisfied: google-auth<2,>=1.6.3 in /usr/local/lib/python3.7/dist-packages (from tensorboard~=2.6->tensorflow) (1.35.0)\n",
            "Requirement already satisfied: requests<3,>=2.21.0 in /usr/local/lib/python3.7/dist-packages (from tensorboard~=2.6->tensorflow) (2.23.0)\n",
            "Requirement already satisfied: markdown>=2.6.8 in /usr/local/lib/python3.7/dist-packages (from tensorboard~=2.6->tensorflow) (3.3.4)\n",
            "Requirement already satisfied: werkzeug>=0.11.15 in /usr/local/lib/python3.7/dist-packages (from tensorboard~=2.6->tensorflow) (1.0.1)\n",
            "Requirement already satisfied: rsa<5,>=3.1.4 in /usr/local/lib/python3.7/dist-packages (from google-auth<2,>=1.6.3->tensorboard~=2.6->tensorflow) (4.7.2)\n",
            "Requirement already satisfied: cachetools<5.0,>=2.0.0 in /usr/local/lib/python3.7/dist-packages (from google-auth<2,>=1.6.3->tensorboard~=2.6->tensorflow) (4.2.4)\n",
            "Requirement already satisfied: pyasn1-modules>=0.2.1 in /usr/local/lib/python3.7/dist-packages (from google-auth<2,>=1.6.3->tensorboard~=2.6->tensorflow) (0.2.8)\n",
            "Requirement already satisfied: requests-oauthlib>=0.7.0 in /usr/local/lib/python3.7/dist-packages (from google-auth-oauthlib<0.5,>=0.4.1->tensorboard~=2.6->tensorflow) (1.3.0)\n",
            "Requirement already satisfied: importlib-metadata in /usr/local/lib/python3.7/dist-packages (from markdown>=2.6.8->tensorboard~=2.6->tensorflow) (4.8.1)\n",
            "Requirement already satisfied: pyasn1<0.5.0,>=0.4.6 in /usr/local/lib/python3.7/dist-packages (from pyasn1-modules>=0.2.1->google-auth<2,>=1.6.3->tensorboard~=2.6->tensorflow) (0.4.8)\n",
            "Requirement already satisfied: chardet<4,>=3.0.2 in /usr/local/lib/python3.7/dist-packages (from requests<3,>=2.21.0->tensorboard~=2.6->tensorflow) (3.0.4)\n",
            "Requirement already satisfied: idna<3,>=2.5 in /usr/local/lib/python3.7/dist-packages (from requests<3,>=2.21.0->tensorboard~=2.6->tensorflow) (2.10)\n",
            "Requirement already satisfied: certifi>=2017.4.17 in /usr/local/lib/python3.7/dist-packages (from requests<3,>=2.21.0->tensorboard~=2.6->tensorflow) (2021.5.30)\n",
            "Requirement already satisfied: urllib3!=1.25.0,!=1.25.1,<1.26,>=1.21.1 in /usr/local/lib/python3.7/dist-packages (from requests<3,>=2.21.0->tensorboard~=2.6->tensorflow) (1.24.3)\n",
            "Requirement already satisfied: oauthlib>=3.0.0 in /usr/local/lib/python3.7/dist-packages (from requests-oauthlib>=0.7.0->google-auth-oauthlib<0.5,>=0.4.1->tensorboard~=2.6->tensorflow) (3.1.1)\n",
            "Requirement already satisfied: zipp>=0.5 in /usr/local/lib/python3.7/dist-packages (from importlib-metadata->markdown>=2.6.8->tensorboard~=2.6->tensorflow) (3.6.0)\n"
          ]
        }
      ]
    },
    {
      "cell_type": "code",
      "metadata": {
        "colab": {
          "base_uri": "https://localhost:8080/"
        },
        "id": "8jdNKFSxIWUu",
        "outputId": "0a2dd3cd-eb4b-4987-e4ad-99378d0b35e1"
      },
      "source": [
        "!pip install -U ipykernel"
      ],
      "execution_count": null,
      "outputs": [
        {
          "output_type": "stream",
          "name": "stdout",
          "text": [
            "Requirement already satisfied: ipykernel in /usr/local/lib/python3.7/dist-packages (6.4.1)\n",
            "Requirement already satisfied: jupyter-client<8.0 in /usr/local/lib/python3.7/dist-packages (from ipykernel) (5.3.5)\n",
            "Requirement already satisfied: matplotlib-inline<0.2.0,>=0.1.0 in /usr/local/lib/python3.7/dist-packages (from ipykernel) (0.1.3)\n",
            "Requirement already satisfied: importlib-metadata<5 in /usr/local/lib/python3.7/dist-packages (from ipykernel) (4.8.1)\n",
            "Requirement already satisfied: tornado<7.0,>=4.2 in /usr/local/lib/python3.7/dist-packages (from ipykernel) (5.1.1)\n",
            "Requirement already satisfied: argcomplete>=1.12.3 in /usr/local/lib/python3.7/dist-packages (from ipykernel) (1.12.3)\n",
            "Requirement already satisfied: ipython<8.0,>=7.23.1 in /usr/local/lib/python3.7/dist-packages (from ipykernel) (7.28.0)\n",
            "Requirement already satisfied: traitlets<6.0,>=4.1.0 in /usr/local/lib/python3.7/dist-packages (from ipykernel) (5.1.0)\n",
            "Requirement already satisfied: debugpy<2.0,>=1.0.0 in /usr/local/lib/python3.7/dist-packages (from ipykernel) (1.0.0)\n",
            "Requirement already satisfied: ipython-genutils in /usr/local/lib/python3.7/dist-packages (from ipykernel) (0.2.0)\n",
            "Requirement already satisfied: zipp>=0.5 in /usr/local/lib/python3.7/dist-packages (from importlib-metadata<5->ipykernel) (3.6.0)\n",
            "Requirement already satisfied: typing-extensions>=3.6.4 in /usr/local/lib/python3.7/dist-packages (from importlib-metadata<5->ipykernel) (3.7.4.3)\n",
            "Requirement already satisfied: setuptools>=18.5 in /usr/local/lib/python3.7/dist-packages (from ipython<8.0,>=7.23.1->ipykernel) (57.4.0)\n",
            "Requirement already satisfied: prompt-toolkit!=3.0.0,!=3.0.1,<3.1.0,>=2.0.0 in /usr/local/lib/python3.7/dist-packages (from ipython<8.0,>=7.23.1->ipykernel) (3.0.20)\n",
            "Requirement already satisfied: jedi>=0.16 in /usr/local/lib/python3.7/dist-packages (from ipython<8.0,>=7.23.1->ipykernel) (0.18.0)\n",
            "Requirement already satisfied: pygments in /usr/local/lib/python3.7/dist-packages (from ipython<8.0,>=7.23.1->ipykernel) (2.6.1)\n",
            "Requirement already satisfied: backcall in /usr/local/lib/python3.7/dist-packages (from ipython<8.0,>=7.23.1->ipykernel) (0.2.0)\n",
            "Requirement already satisfied: pexpect>4.3 in /usr/local/lib/python3.7/dist-packages (from ipython<8.0,>=7.23.1->ipykernel) (4.8.0)\n",
            "Requirement already satisfied: pickleshare in /usr/local/lib/python3.7/dist-packages (from ipython<8.0,>=7.23.1->ipykernel) (0.7.5)\n",
            "Requirement already satisfied: decorator in /usr/local/lib/python3.7/dist-packages (from ipython<8.0,>=7.23.1->ipykernel) (4.4.2)\n",
            "Requirement already satisfied: parso<0.9.0,>=0.8.0 in /usr/local/lib/python3.7/dist-packages (from jedi>=0.16->ipython<8.0,>=7.23.1->ipykernel) (0.8.2)\n",
            "Requirement already satisfied: python-dateutil>=2.1 in /usr/local/lib/python3.7/dist-packages (from jupyter-client<8.0->ipykernel) (2.8.2)\n",
            "Requirement already satisfied: pyzmq>=13 in /usr/local/lib/python3.7/dist-packages (from jupyter-client<8.0->ipykernel) (22.3.0)\n",
            "Requirement already satisfied: jupyter-core>=4.6.0 in /usr/local/lib/python3.7/dist-packages (from jupyter-client<8.0->ipykernel) (4.8.1)\n",
            "Requirement already satisfied: ptyprocess>=0.5 in /usr/local/lib/python3.7/dist-packages (from pexpect>4.3->ipython<8.0,>=7.23.1->ipykernel) (0.7.0)\n",
            "Requirement already satisfied: wcwidth in /usr/local/lib/python3.7/dist-packages (from prompt-toolkit!=3.0.0,!=3.0.1,<3.1.0,>=2.0.0->ipython<8.0,>=7.23.1->ipykernel) (0.2.5)\n",
            "Requirement already satisfied: six>=1.5 in /usr/local/lib/python3.7/dist-packages (from python-dateutil>=2.1->jupyter-client<8.0->ipykernel) (1.15.0)\n"
          ]
        }
      ]
    },
    {
      "cell_type": "code",
      "metadata": {
        "colab": {
          "base_uri": "https://localhost:8080/"
        },
        "id": "e4cpX06SIk2j",
        "outputId": "63bb2bcc-4a9d-41ef-9d7c-096eb8b78e9d"
      },
      "source": [
        "!pip install -q streamlit"
      ],
      "execution_count": null,
      "outputs": [
        {
          "output_type": "stream",
          "name": "stdout",
          "text": [
            "\u001b[K     |████████████████████████████████| 8.3 MB 6.2 MB/s \n",
            "\u001b[K     |████████████████████████████████| 4.3 MB 45.9 MB/s \n",
            "\u001b[K     |████████████████████████████████| 111 kB 72.5 MB/s \n",
            "\u001b[K     |████████████████████████████████| 180 kB 52.2 MB/s \n",
            "\u001b[K     |████████████████████████████████| 76 kB 5.8 MB/s \n",
            "\u001b[K     |████████████████████████████████| 63 kB 2.2 MB/s \n",
            "\u001b[?25h  Building wheel for blinker (setup.py) ... \u001b[?25l\u001b[?25hdone\n"
          ]
        }
      ]
    },
    {
      "cell_type": "code",
      "metadata": {
        "colab": {
          "base_uri": "https://localhost:8080/"
        },
        "id": "E5ZrlqtzIpXp",
        "outputId": "3708b334-009c-4180-bd46-11da335a48f0"
      },
      "source": [
        "!pip install pyngrok==4.1.1"
      ],
      "execution_count": null,
      "outputs": [
        {
          "output_type": "stream",
          "name": "stdout",
          "text": [
            "Collecting pyngrok==4.1.1\n",
            "  Downloading pyngrok-4.1.1.tar.gz (18 kB)\n",
            "Requirement already satisfied: future in /usr/local/lib/python3.7/dist-packages (from pyngrok==4.1.1) (0.16.0)\n",
            "Requirement already satisfied: PyYAML in /usr/local/lib/python3.7/dist-packages (from pyngrok==4.1.1) (3.13)\n",
            "Building wheels for collected packages: pyngrok\n",
            "  Building wheel for pyngrok (setup.py) ... \u001b[?25l\u001b[?25hdone\n",
            "  Created wheel for pyngrok: filename=pyngrok-4.1.1-py3-none-any.whl size=15984 sha256=07f95fbe3030c7a73f5175b62c9098a690d420be7ba720b94466f17c8554171e\n",
            "  Stored in directory: /root/.cache/pip/wheels/b1/d9/12/045a042fee3127dc40ba6f5df2798aa2df38c414bf533ca765\n",
            "Successfully built pyngrok\n",
            "Installing collected packages: pyngrok\n",
            "Successfully installed pyngrok-4.1.1\n"
          ]
        }
      ]
    },
    {
      "cell_type": "code",
      "metadata": {
        "colab": {
          "base_uri": "https://localhost:8080/"
        },
        "id": "NYcD7fG9JpSR",
        "outputId": "3b594e8b-a7b3-40d7-edde-3dac38a3726a"
      },
      "source": [
        "!ngrok authtoken 1zYCvpfYS9ArNYYZux0gFUn1pTZ_82Mm5Kw7NRUJQ54AWth8j"
      ],
      "execution_count": null,
      "outputs": [
        {
          "output_type": "stream",
          "name": "stdout",
          "text": [
            "Authtoken saved to configuration file: /root/.ngrok2/ngrok.yml\n"
          ]
        }
      ]
    },
    {
      "cell_type": "code",
      "metadata": {
        "id": "xss122Q9WAT7"
      },
      "source": [
        "#path = st.text_input('Enter Image URL TO classify...', 'https://www.climatechangepost.com/media/news/2020/01/Extreme_wildfire_event.jpg.820x520_q95_crop-smart.jpg')\n",
        "#if path is not None:\n",
        "  #content = requests.get(path).content #conversion of URL to byte array"
      ],
      "execution_count": null,
      "outputs": []
    },
    {
      "cell_type": "code",
      "metadata": {
        "id": "FWgya414rI9V"
      },
      "source": [
        "%%writefile score.py\n",
        "\n",
        "import tensorflow as tf\n",
        "import numpy as np\n",
        "import streamlit as st\n",
        "from PIL import Image\n",
        "import requests\n",
        "from io import BytesIO\n",
        "import keras_preprocessing\n",
        "from keras_preprocessing import image\n",
        "from keras_preprocessing.image import ImageDataGenerator\n",
        "\n",
        "st.set_option('deprecation.showfileUploaderEncoding', False)\n",
        "st.title(\"Fire Detection Classifier\")\n",
        "st.text(\"Provide URL of Fire Image for Image Classification\")\n",
        "\n",
        "@st.cache(allow_output_mutation=True)\n",
        "def load_model():\n",
        "  model = tf.keras.models.load_model('/content/drive/MyDrive/trained weights/inception_fire_model.h5')\n",
        "  return model\n",
        "\n",
        "with st.spinner('Loading Model into Memory......'):\n",
        "  model = load_model()\n",
        "\n",
        "classes =['Fire','Neutral(No Fire)']\n",
        "\n",
        "def scale(image):\n",
        "  image = tf.cast(image, tf.float32)\n",
        "  image /= 255.0\n",
        "\n",
        "  return tf.image.resize(image,[224,224])\n",
        "\n",
        "def decode_img(image):\n",
        "  img = tf.image.decode_jpeg(image, channels=3)\n",
        "  img = scale(img)\n",
        "  return np.expand_dims(img, axis =0)\n",
        "\n",
        "path = st.text_input('Enter Image URL TO classify...', 'https://www.climatechangepost.com/media/news/2020/01/Extreme_wildfire_event.jpg.820x520_q95_crop-smart.jpg')\n",
        "if path is not None:\n",
        "  content = requests.get(path).content #conversion of URL to byte array\n",
        "\n",
        "  st.write(\"Predicted Class:\")\n",
        "  with st.spinner('classifying......'):\n",
        "    label = np.argmax(model.predict(decode_img(content)), axis=1)\n",
        "    st.write(classes[label[0]])\n",
        "  st.write(\"\")\n",
        "  image = Image.open(BytesIO(content))\n",
        "  st.image(image, caption='Classifying Image', use_column_width=True)"
      ],
      "execution_count": null,
      "outputs": []
    },
    {
      "cell_type": "code",
      "metadata": {
        "colab": {
          "base_uri": "https://localhost:8080/"
        },
        "id": "7StWsfqmbbFY",
        "outputId": "db94255e-3094-4bb2-880d-cdf941f1dbad"
      },
      "source": [
        "!nohup streamlit run score.py &"
      ],
      "execution_count": null,
      "outputs": [
        {
          "output_type": "stream",
          "name": "stdout",
          "text": [
            "nohup: appending output to 'nohup.out'\n"
          ]
        }
      ]
    },
    {
      "cell_type": "code",
      "metadata": {
        "colab": {
          "base_uri": "https://localhost:8080/",
          "height": 35
        },
        "id": "i9G1N_iwbqhh",
        "outputId": "eb6736dc-0388-4359-a4bc-fa17d78b6da3"
      },
      "source": [
        "from pyngrok import ngrok\n",
        "\n",
        "url = ngrok.connect(port=8501)\n",
        "url"
      ],
      "execution_count": null,
      "outputs": [
        {
          "output_type": "execute_result",
          "data": {
            "application/vnd.google.colaboratory.intrinsic+json": {
              "type": "string"
            },
            "text/plain": [
              "'http://b613-34-125-81-210.ngrok.io'"
            ]
          },
          "metadata": {},
          "execution_count": 8
        }
      ]
    },
    {
      "cell_type": "code",
      "metadata": {
        "colab": {
          "base_uri": "https://localhost:8080/"
        },
        "id": "-aw4BOEzcgAI",
        "outputId": "e919b366-d885-4bae-ffc9-26c48d27c916"
      },
      "source": [
        "!cat nohup.out"
      ],
      "execution_count": null,
      "outputs": [
        {
          "output_type": "stream",
          "name": "stdout",
          "text": [
            "\n",
            "  You can now view your Streamlit app in your browser.\n",
            "\n",
            "  Network URL: http://172.28.0.2:8501\n",
            "  External URL: http://34.125.81.210:8501\n",
            "\n",
            "\n",
            "  You can now view your Streamlit app in your browser.\n",
            "\n",
            "  Network URL: http://172.28.0.2:8502\n",
            "  External URL: http://34.125.81.210:8502\n",
            "\n",
            "\n",
            "  You can now view your Streamlit app in your browser.\n",
            "\n",
            "  Network URL: http://172.28.0.2:8503\n",
            "  External URL: http://34.125.81.210:8503\n",
            "\n",
            "\n",
            "  You can now view your Streamlit app in your browser.\n",
            "\n",
            "  Network URL: http://172.28.0.2:8504\n",
            "  External URL: http://34.125.81.210:8504\n",
            "\n",
            "2021-10-15 16:55:24.802 Traceback (most recent call last):\n",
            "  File \"/usr/local/lib/python3.7/dist-packages/streamlit/script_runner.py\", line 354, in _run_script\n",
            "    exec(code, module.__dict__)\n",
            "  File \"/content/score.py\", line 12, in <module>\n",
            "    st.set_option('deprecation.showfileUploderEncoding', False)\n",
            "  File \"/usr/local/lib/python3.7/dist-packages/streamlit/__init__.py\", line 230, in set_option\n",
            "    opt = _config._config_options_template[key]\n",
            "KeyError: 'deprecation.showfileUploderEncoding'\n",
            "\n",
            "2021-10-15 16:55:31.648 Traceback (most recent call last):\n",
            "  File \"/usr/local/lib/python3.7/dist-packages/streamlit/script_runner.py\", line 354, in _run_script\n",
            "    exec(code, module.__dict__)\n",
            "  File \"/content/score.py\", line 12, in <module>\n",
            "    st.set_option('deprecation.showfileUploderEncoding', False)\n",
            "  File \"/usr/local/lib/python3.7/dist-packages/streamlit/__init__.py\", line 230, in set_option\n",
            "    opt = _config._config_options_template[key]\n",
            "KeyError: 'deprecation.showfileUploderEncoding'\n",
            "\n",
            "\n",
            "  You can now view your Streamlit app in your browser.\n",
            "\n",
            "  Network URL: http://172.28.0.2:8505\n",
            "  External URL: http://34.125.81.210:8505\n",
            "\n",
            "2021-10-15 16:56:35.295452: E tensorflow/stream_executor/cuda/cuda_driver.cc:271] failed call to cuInit: CUDA_ERROR_NO_DEVICE: no CUDA-capable device is detected\n",
            "2021-10-15 16:56:35.296067: I tensorflow/stream_executor/cuda/cuda_diagnostics.cc:156] kernel driver does not appear to be running on this host (e283ac559329): /proc/driver/nvidia/version does not exist\n",
            "2021-10-15 16:56:41.437848: E tensorflow/stream_executor/cuda/cuda_driver.cc:271] failed call to cuInit: CUDA_ERROR_NO_DEVICE: no CUDA-capable device is detected\n",
            "2021-10-15 16:56:41.438250: I tensorflow/stream_executor/cuda/cuda_diagnostics.cc:156] kernel driver does not appear to be running on this host (e283ac559329): /proc/driver/nvidia/version does not exist\n",
            "2021-10-15 16:56:44.268357: I tensorflow/compiler/mlir/mlir_graph_optimization_pass.cc:185] None of the MLIR Optimization Passes are enabled (registered 2)\n",
            "2021-10-15 16:56:45.356593: I tensorflow/compiler/mlir/mlir_graph_optimization_pass.cc:185] None of the MLIR Optimization Passes are enabled (registered 2)\n",
            "2021-10-15 17:03:02.222 Traceback (most recent call last):\n",
            "  File \"/usr/local/lib/python3.7/dist-packages/streamlit/script_runner.py\", line 354, in _run_script\n",
            "    exec(code, module.__dict__)\n",
            "  File \"/content/score.py\", line 39, in <module>\n",
            "    content = requests.get(path).content #conversion of URL to byte array\n",
            "  File \"/usr/local/lib/python3.7/dist-packages/requests/api.py\", line 76, in get\n",
            "    return request('get', url, params=params, **kwargs)\n",
            "  File \"/usr/local/lib/python3.7/dist-packages/requests/api.py\", line 61, in request\n",
            "    return session.request(method=method, url=url, **kwargs)\n",
            "  File \"/usr/local/lib/python3.7/dist-packages/requests/sessions.py\", line 516, in request\n",
            "    prep = self.prepare_request(req)\n",
            "  File \"/usr/local/lib/python3.7/dist-packages/requests/sessions.py\", line 459, in prepare_request\n",
            "    hooks=merge_hooks(request.hooks, self.hooks),\n",
            "  File \"/usr/local/lib/python3.7/dist-packages/requests/models.py\", line 314, in prepare\n",
            "    self.prepare_url(url, params)\n",
            "  File \"/usr/local/lib/python3.7/dist-packages/requests/models.py\", line 388, in prepare_url\n",
            "    raise MissingSchema(error)\n",
            "requests.exceptions.MissingSchema: Invalid URL '': No schema supplied. Perhaps you meant http://?\n",
            "\n",
            "\n",
            "  You can now view your Streamlit app in your browser.\n",
            "\n",
            "  Network URL: http://172.28.0.2:8506\n",
            "  External URL: http://34.125.81.210:8506\n",
            "\n",
            "2021-10-15 17:07:52.693311: E tensorflow/stream_executor/cuda/cuda_driver.cc:271] failed call to cuInit: CUDA_ERROR_NO_DEVICE: no CUDA-capable device is detected\n",
            "2021-10-15 17:07:52.693846: I tensorflow/stream_executor/cuda/cuda_diagnostics.cc:156] kernel driver does not appear to be running on this host (e283ac559329): /proc/driver/nvidia/version does not exist\n",
            "2021-10-15 17:07:56.191780: I tensorflow/compiler/mlir/mlir_graph_optimization_pass.cc:185] None of the MLIR Optimization Passes are enabled (registered 2)\n",
            "2021-10-15 17:11:23.561 Traceback (most recent call last):\n",
            "  File \"/usr/local/lib/python3.7/dist-packages/streamlit/script_runner.py\", line 354, in _run_script\n",
            "    exec(code, module.__dict__)\n",
            "  File \"/content/score.py\", line 39, in <module>\n",
            "    content = requests.get(path).content #conversion of URL to byte array\n",
            "  File \"/usr/local/lib/python3.7/dist-packages/requests/api.py\", line 76, in get\n",
            "    return request('get', url, params=params, **kwargs)\n",
            "  File \"/usr/local/lib/python3.7/dist-packages/requests/api.py\", line 61, in request\n",
            "    return session.request(method=method, url=url, **kwargs)\n",
            "  File \"/usr/local/lib/python3.7/dist-packages/requests/sessions.py\", line 516, in request\n",
            "    prep = self.prepare_request(req)\n",
            "  File \"/usr/local/lib/python3.7/dist-packages/requests/sessions.py\", line 459, in prepare_request\n",
            "    hooks=merge_hooks(request.hooks, self.hooks),\n",
            "  File \"/usr/local/lib/python3.7/dist-packages/requests/models.py\", line 314, in prepare\n",
            "    self.prepare_url(url, params)\n",
            "  File \"/usr/local/lib/python3.7/dist-packages/requests/models.py\", line 388, in prepare_url\n",
            "    raise MissingSchema(error)\n",
            "requests.exceptions.MissingSchema: Invalid URL '': No schema supplied. Perhaps you meant http://?\n",
            "\n",
            "2021-10-15 17:15:45.808 Traceback (most recent call last):\n",
            "  File \"/usr/local/lib/python3.7/dist-packages/streamlit/script_runner.py\", line 354, in _run_script\n",
            "    exec(code, module.__dict__)\n",
            "  File \"/content/score.py\", line 39, in <module>\n",
            "    content = requests.get(path).content #conversion of URL to byte array\n",
            "  File \"/usr/local/lib/python3.7/dist-packages/requests/api.py\", line 76, in get\n",
            "    return request('get', url, params=params, **kwargs)\n",
            "  File \"/usr/local/lib/python3.7/dist-packages/requests/api.py\", line 61, in request\n",
            "    return session.request(method=method, url=url, **kwargs)\n",
            "  File \"/usr/local/lib/python3.7/dist-packages/requests/sessions.py\", line 516, in request\n",
            "    prep = self.prepare_request(req)\n",
            "  File \"/usr/local/lib/python3.7/dist-packages/requests/sessions.py\", line 459, in prepare_request\n",
            "    hooks=merge_hooks(request.hooks, self.hooks),\n",
            "  File \"/usr/local/lib/python3.7/dist-packages/requests/models.py\", line 314, in prepare\n",
            "    self.prepare_url(url, params)\n",
            "  File \"/usr/local/lib/python3.7/dist-packages/requests/models.py\", line 388, in prepare_url\n",
            "    raise MissingSchema(error)\n",
            "requests.exceptions.MissingSchema: Invalid URL '': No schema supplied. Perhaps you meant http://?\n",
            "\n",
            "2021-10-15 17:42:20.182 Traceback (most recent call last):\n",
            "  File \"/usr/local/lib/python3.7/dist-packages/streamlit/script_runner.py\", line 354, in _run_script\n",
            "    exec(code, module.__dict__)\n",
            "  File \"/content/score.py\", line 43, in <module>\n",
            "    label = np.argmax(model.predict(decode_img(content)), axis=1)\n",
            "  File \"/content/score.py\", line 33, in decode_img\n",
            "    img = tf.image.decode_jpeg(image, channels=3)\n",
            "  File \"/usr/local/lib/python3.7/dist-packages/tensorflow/python/ops/gen_image_ops.py\", line 1175, in decode_jpeg\n",
            "    name=name, ctx=_ctx)\n",
            "  File \"/usr/local/lib/python3.7/dist-packages/tensorflow/python/ops/gen_image_ops.py\", line 1245, in decode_jpeg_eager_fallback\n",
            "    attrs=_attrs, ctx=ctx, name=name)\n",
            "  File \"/usr/local/lib/python3.7/dist-packages/tensorflow/python/eager/execute.py\", line 60, in quick_execute\n",
            "    inputs, attrs, num_outputs)\n",
            "tensorflow.python.framework.errors_impl.InvalidArgumentError: Unknown image file format. One of JPEG, PNG, GIF, BMP required. [Op:DecodeJpeg]\n",
            "\n",
            "2021-10-15 17:42:39.319 Traceback (most recent call last):\n",
            "  File \"/usr/local/lib/python3.7/dist-packages/streamlit/script_runner.py\", line 354, in _run_script\n",
            "    exec(code, module.__dict__)\n",
            "  File \"/content/score.py\", line 39, in <module>\n",
            "    content = requests.get(path).content #conversion of URL to byte array\n",
            "  File \"/usr/local/lib/python3.7/dist-packages/requests/api.py\", line 76, in get\n",
            "    return request('get', url, params=params, **kwargs)\n",
            "  File \"/usr/local/lib/python3.7/dist-packages/requests/api.py\", line 61, in request\n",
            "    return session.request(method=method, url=url, **kwargs)\n",
            "  File \"/usr/local/lib/python3.7/dist-packages/requests/sessions.py\", line 516, in request\n",
            "    prep = self.prepare_request(req)\n",
            "  File \"/usr/local/lib/python3.7/dist-packages/requests/sessions.py\", line 459, in prepare_request\n",
            "    hooks=merge_hooks(request.hooks, self.hooks),\n",
            "  File \"/usr/local/lib/python3.7/dist-packages/requests/models.py\", line 314, in prepare\n",
            "    self.prepare_url(url, params)\n",
            "  File \"/usr/local/lib/python3.7/dist-packages/requests/models.py\", line 388, in prepare_url\n",
            "    raise MissingSchema(error)\n",
            "requests.exceptions.MissingSchema: Invalid URL '': No schema supplied. Perhaps you meant http://?\n",
            "\n",
            "2021-10-15 17:44:48.788 Traceback (most recent call last):\n",
            "  File \"/usr/local/lib/python3.7/dist-packages/streamlit/script_runner.py\", line 354, in _run_script\n",
            "    exec(code, module.__dict__)\n",
            "  File \"/content/score.py\", line 39, in <module>\n",
            "    content = requests.get(path).content #conversion of URL to byte array\n",
            "  File \"/usr/local/lib/python3.7/dist-packages/requests/api.py\", line 76, in get\n",
            "    return request('get', url, params=params, **kwargs)\n",
            "  File \"/usr/local/lib/python3.7/dist-packages/requests/api.py\", line 61, in request\n",
            "    return session.request(method=method, url=url, **kwargs)\n",
            "  File \"/usr/local/lib/python3.7/dist-packages/requests/sessions.py\", line 516, in request\n",
            "    prep = self.prepare_request(req)\n",
            "  File \"/usr/local/lib/python3.7/dist-packages/requests/sessions.py\", line 459, in prepare_request\n",
            "    hooks=merge_hooks(request.hooks, self.hooks),\n",
            "  File \"/usr/local/lib/python3.7/dist-packages/requests/models.py\", line 314, in prepare\n",
            "    self.prepare_url(url, params)\n",
            "  File \"/usr/local/lib/python3.7/dist-packages/requests/models.py\", line 388, in prepare_url\n",
            "    raise MissingSchema(error)\n",
            "requests.exceptions.MissingSchema: Invalid URL '': No schema supplied. Perhaps you meant http://?\n",
            "\n",
            "2021-10-15 17:46:22.159 Traceback (most recent call last):\n",
            "  File \"/usr/local/lib/python3.7/dist-packages/streamlit/script_runner.py\", line 354, in _run_script\n",
            "    exec(code, module.__dict__)\n",
            "  File \"/content/score.py\", line 43, in <module>\n",
            "    label = np.argmax(model.predict(decode_img(content)), axis=1)\n",
            "  File \"/content/score.py\", line 33, in decode_img\n",
            "    img = tf.image.decode_jpeg(image, channels=3)\n",
            "  File \"/usr/local/lib/python3.7/dist-packages/tensorflow/python/ops/gen_image_ops.py\", line 1175, in decode_jpeg\n",
            "    name=name, ctx=_ctx)\n",
            "  File \"/usr/local/lib/python3.7/dist-packages/tensorflow/python/ops/gen_image_ops.py\", line 1245, in decode_jpeg_eager_fallback\n",
            "    attrs=_attrs, ctx=ctx, name=name)\n",
            "  File \"/usr/local/lib/python3.7/dist-packages/tensorflow/python/eager/execute.py\", line 60, in quick_execute\n",
            "    inputs, attrs, num_outputs)\n",
            "tensorflow.python.framework.errors_impl.InvalidArgumentError: Unknown image file format. One of JPEG, PNG, GIF, BMP required. [Op:DecodeJpeg]\n",
            "\n",
            "\n",
            "  You can now view your Streamlit app in your browser.\n",
            "\n",
            "  Network URL: http://172.28.0.2:8507\n",
            "  External URL: http://34.125.81.210:8507\n",
            "\n",
            "2021-10-15 17:47:06.375731: E tensorflow/stream_executor/cuda/cuda_driver.cc:271] failed call to cuInit: CUDA_ERROR_NO_DEVICE: no CUDA-capable device is detected\n",
            "2021-10-15 17:47:06.376713: I tensorflow/stream_executor/cuda/cuda_diagnostics.cc:156] kernel driver does not appear to be running on this host (e283ac559329): /proc/driver/nvidia/version does not exist\n",
            "2021-10-15 17:47:10.171873: I tensorflow/compiler/mlir/mlir_graph_optimization_pass.cc:185] None of the MLIR Optimization Passes are enabled (registered 2)\n",
            "2021-10-15 18:01:17.821 Traceback (most recent call last):\n",
            "  File \"/usr/local/lib/python3.7/dist-packages/urllib3/connection.py\", line 159, in _new_conn\n",
            "    (self._dns_host, self.port), self.timeout, **extra_kw)\n",
            "  File \"/usr/local/lib/python3.7/dist-packages/urllib3/util/connection.py\", line 57, in create_connection\n",
            "    for res in socket.getaddrinfo(host, port, family, socket.SOCK_STREAM):\n",
            "  File \"/usr/lib/python3.7/socket.py\", line 752, in getaddrinfo\n",
            "    for res in _socket.getaddrinfo(host, port, family, type, proto, flags):\n",
            "socket.gaierror: [Errno -2] Name or service not known\n",
            "\n",
            "During handling of the above exception, another exception occurred:\n",
            "\n",
            "Traceback (most recent call last):\n",
            "  File \"/usr/local/lib/python3.7/dist-packages/urllib3/connectionpool.py\", line 600, in urlopen\n",
            "    chunked=chunked)\n",
            "  File \"/usr/local/lib/python3.7/dist-packages/urllib3/connectionpool.py\", line 343, in _make_request\n",
            "    self._validate_conn(conn)\n",
            "  File \"/usr/local/lib/python3.7/dist-packages/urllib3/connectionpool.py\", line 839, in _validate_conn\n",
            "    conn.connect()\n",
            "  File \"/usr/local/lib/python3.7/dist-packages/urllib3/connection.py\", line 301, in connect\n",
            "    conn = self._new_conn()\n",
            "  File \"/usr/local/lib/python3.7/dist-packages/urllib3/connection.py\", line 168, in _new_conn\n",
            "    self, \"Failed to establish a new connection: %s\" % e)\n",
            "urllib3.exceptions.NewConnectionError: <urllib3.connection.VerifiedHTTPSConnection object at 0x7f54f5c03d90>: Failed to establish a new connection: [Errno -2] Name or service not known\n",
            "\n",
            "During handling of the above exception, another exception occurred:\n",
            "\n",
            "Traceback (most recent call last):\n",
            "  File \"/usr/local/lib/python3.7/dist-packages/requests/adapters.py\", line 449, in send\n",
            "    timeout=timeout\n",
            "  File \"/usr/local/lib/python3.7/dist-packages/urllib3/connectionpool.py\", line 638, in urlopen\n",
            "    _stacktrace=sys.exc_info()[2])\n",
            "  File \"/usr/local/lib/python3.7/dist-packages/urllib3/util/retry.py\", line 399, in increment\n",
            "    raise MaxRetryError(_pool, url, error or ResponseError(cause))\n",
            "urllib3.exceptions.MaxRetryError: HTTPSConnectionPool(host='www.climatechangepost.g.820x520_q95_crop-smart.jpg', port=443): Max retries exceeded with url: / (Caused by NewConnectionError('<urllib3.connection.VerifiedHTTPSConnection object at 0x7f54f5c03d90>: Failed to establish a new connection: [Errno -2] Name or service not known'))\n",
            "\n",
            "During handling of the above exception, another exception occurred:\n",
            "\n",
            "Traceback (most recent call last):\n",
            "  File \"/usr/local/lib/python3.7/dist-packages/streamlit/script_runner.py\", line 354, in _run_script\n",
            "    exec(code, module.__dict__)\n",
            "  File \"/content/score.py\", line 39, in <module>\n",
            "    content = requests.get(path).content #conversion of URL to byte array\n",
            "  File \"/usr/local/lib/python3.7/dist-packages/requests/api.py\", line 76, in get\n",
            "    return request('get', url, params=params, **kwargs)\n",
            "  File \"/usr/local/lib/python3.7/dist-packages/requests/api.py\", line 61, in request\n",
            "    return session.request(method=method, url=url, **kwargs)\n",
            "  File \"/usr/local/lib/python3.7/dist-packages/requests/sessions.py\", line 530, in request\n",
            "    resp = self.send(prep, **send_kwargs)\n",
            "  File \"/usr/local/lib/python3.7/dist-packages/requests/sessions.py\", line 643, in send\n",
            "    r = adapter.send(request, **kwargs)\n",
            "  File \"/usr/local/lib/python3.7/dist-packages/requests/adapters.py\", line 516, in send\n",
            "    raise ConnectionError(e, request=request)\n",
            "requests.exceptions.ConnectionError: HTTPSConnectionPool(host='www.climatechangepost.g.820x520_q95_crop-smart.jpg', port=443): Max retries exceeded with url: / (Caused by NewConnectionError('<urllib3.connection.VerifiedHTTPSConnection object at 0x7f54f5c03d90>: Failed to establish a new connection: [Errno -2] Name or service not known'))\n",
            "\n",
            "2021-10-15 18:02:35.576 Traceback (most recent call last):\n",
            "  File \"/usr/local/lib/python3.7/dist-packages/streamlit/script_runner.py\", line 354, in _run_script\n",
            "    exec(code, module.__dict__)\n",
            "  File \"/content/score.py\", line 39, in <module>\n",
            "    content = requests.get(path).content #conversion of URL to byte array\n",
            "  File \"/usr/local/lib/python3.7/dist-packages/requests/api.py\", line 76, in get\n",
            "    return request('get', url, params=params, **kwargs)\n",
            "  File \"/usr/local/lib/python3.7/dist-packages/requests/api.py\", line 61, in request\n",
            "    return session.request(method=method, url=url, **kwargs)\n",
            "  File \"/usr/local/lib/python3.7/dist-packages/requests/sessions.py\", line 516, in request\n",
            "    prep = self.prepare_request(req)\n",
            "  File \"/usr/local/lib/python3.7/dist-packages/requests/sessions.py\", line 459, in prepare_request\n",
            "    hooks=merge_hooks(request.hooks, self.hooks),\n",
            "  File \"/usr/local/lib/python3.7/dist-packages/requests/models.py\", line 314, in prepare\n",
            "    self.prepare_url(url, params)\n",
            "  File \"/usr/local/lib/python3.7/dist-packages/requests/models.py\", line 388, in prepare_url\n",
            "    raise MissingSchema(error)\n",
            "requests.exceptions.MissingSchema: Invalid URL '': No schema supplied. Perhaps you meant http://?\n",
            "\n",
            "2021-10-15 18:02:51.025 Traceback (most recent call last):\n",
            "  File \"/usr/local/lib/python3.7/dist-packages/streamlit/script_runner.py\", line 354, in _run_script\n",
            "    exec(code, module.__dict__)\n",
            "  File \"/content/score.py\", line 39, in <module>\n",
            "    content = requests.get(path).content #conversion of URL to byte array\n",
            "  File \"/usr/local/lib/python3.7/dist-packages/requests/api.py\", line 76, in get\n",
            "    return request('get', url, params=params, **kwargs)\n",
            "  File \"/usr/local/lib/python3.7/dist-packages/requests/api.py\", line 61, in request\n",
            "    return session.request(method=method, url=url, **kwargs)\n",
            "  File \"/usr/local/lib/python3.7/dist-packages/requests/sessions.py\", line 516, in request\n",
            "    prep = self.prepare_request(req)\n",
            "  File \"/usr/local/lib/python3.7/dist-packages/requests/sessions.py\", line 459, in prepare_request\n",
            "    hooks=merge_hooks(request.hooks, self.hooks),\n",
            "  File \"/usr/local/lib/python3.7/dist-packages/requests/models.py\", line 314, in prepare\n",
            "    self.prepare_url(url, params)\n",
            "  File \"/usr/local/lib/python3.7/dist-packages/requests/models.py\", line 388, in prepare_url\n",
            "    raise MissingSchema(error)\n",
            "requests.exceptions.MissingSchema: Invalid URL '': No schema supplied. Perhaps you meant http://?\n",
            "\n",
            "2021-10-15 18:07:00.750 Traceback (most recent call last):\n",
            "  File \"/usr/local/lib/python3.7/dist-packages/streamlit/script_runner.py\", line 354, in _run_script\n",
            "    exec(code, module.__dict__)\n",
            "  File \"/content/score.py\", line 39, in <module>\n",
            "    content = requests.get(path).content #conversion of URL to byte array\n",
            "  File \"/usr/local/lib/python3.7/dist-packages/requests/api.py\", line 76, in get\n",
            "    return request('get', url, params=params, **kwargs)\n",
            "  File \"/usr/local/lib/python3.7/dist-packages/requests/api.py\", line 61, in request\n",
            "    return session.request(method=method, url=url, **kwargs)\n",
            "  File \"/usr/local/lib/python3.7/dist-packages/requests/sessions.py\", line 516, in request\n",
            "    prep = self.prepare_request(req)\n",
            "  File \"/usr/local/lib/python3.7/dist-packages/requests/sessions.py\", line 459, in prepare_request\n",
            "    hooks=merge_hooks(request.hooks, self.hooks),\n",
            "  File \"/usr/local/lib/python3.7/dist-packages/requests/models.py\", line 314, in prepare\n",
            "    self.prepare_url(url, params)\n",
            "  File \"/usr/local/lib/python3.7/dist-packages/requests/models.py\", line 388, in prepare_url\n",
            "    raise MissingSchema(error)\n",
            "requests.exceptions.MissingSchema: Invalid URL '': No schema supplied. Perhaps you meant http://?\n",
            "\n",
            "2021-10-15 18:11:44.315 Traceback (most recent call last):\n",
            "  File \"/usr/local/lib/python3.7/dist-packages/streamlit/script_runner.py\", line 354, in _run_script\n",
            "    exec(code, module.__dict__)\n",
            "  File \"/content/score.py\", line 39, in <module>\n",
            "    content = requests.get(path).content #conversion of URL to byte array\n",
            "  File \"/usr/local/lib/python3.7/dist-packages/requests/api.py\", line 76, in get\n",
            "    return request('get', url, params=params, **kwargs)\n",
            "  File \"/usr/local/lib/python3.7/dist-packages/requests/api.py\", line 61, in request\n",
            "    return session.request(method=method, url=url, **kwargs)\n",
            "  File \"/usr/local/lib/python3.7/dist-packages/requests/sessions.py\", line 516, in request\n",
            "    prep = self.prepare_request(req)\n",
            "  File \"/usr/local/lib/python3.7/dist-packages/requests/sessions.py\", line 459, in prepare_request\n",
            "    hooks=merge_hooks(request.hooks, self.hooks),\n",
            "  File \"/usr/local/lib/python3.7/dist-packages/requests/models.py\", line 314, in prepare\n",
            "    self.prepare_url(url, params)\n",
            "  File \"/usr/local/lib/python3.7/dist-packages/requests/models.py\", line 388, in prepare_url\n",
            "    raise MissingSchema(error)\n",
            "requests.exceptions.MissingSchema: Invalid URL '': No schema supplied. Perhaps you meant http://?\n",
            "\n",
            "2021-10-15 18:21:30.232 Traceback (most recent call last):\n",
            "  File \"/usr/local/lib/python3.7/dist-packages/streamlit/script_runner.py\", line 354, in _run_script\n",
            "    exec(code, module.__dict__)\n",
            "  File \"/content/score.py\", line 43, in <module>\n",
            "    label = np.argmax(model.predict(decode_img(content)), axis=1)\n",
            "  File \"/content/score.py\", line 33, in decode_img\n",
            "    img = tf.image.decode_jpeg(image, channels=3)\n",
            "  File \"/usr/local/lib/python3.7/dist-packages/tensorflow/python/ops/gen_image_ops.py\", line 1175, in decode_jpeg\n",
            "    name=name, ctx=_ctx)\n",
            "  File \"/usr/local/lib/python3.7/dist-packages/tensorflow/python/ops/gen_image_ops.py\", line 1245, in decode_jpeg_eager_fallback\n",
            "    attrs=_attrs, ctx=ctx, name=name)\n",
            "  File \"/usr/local/lib/python3.7/dist-packages/tensorflow/python/eager/execute.py\", line 60, in quick_execute\n",
            "    inputs, attrs, num_outputs)\n",
            "tensorflow.python.framework.errors_impl.InvalidArgumentError: Unknown image file format. One of JPEG, PNG, GIF, BMP required. [Op:DecodeJpeg]\n",
            "\n",
            "2021-10-15 18:21:52.776 Traceback (most recent call last):\n",
            "  File \"/usr/local/lib/python3.7/dist-packages/streamlit/script_runner.py\", line 354, in _run_script\n",
            "    exec(code, module.__dict__)\n",
            "  File \"/content/score.py\", line 39, in <module>\n",
            "    content = requests.get(path).content #conversion of URL to byte array\n",
            "  File \"/usr/local/lib/python3.7/dist-packages/requests/api.py\", line 76, in get\n",
            "    return request('get', url, params=params, **kwargs)\n",
            "  File \"/usr/local/lib/python3.7/dist-packages/requests/api.py\", line 61, in request\n",
            "    return session.request(method=method, url=url, **kwargs)\n",
            "  File \"/usr/local/lib/python3.7/dist-packages/requests/sessions.py\", line 516, in request\n",
            "    prep = self.prepare_request(req)\n",
            "  File \"/usr/local/lib/python3.7/dist-packages/requests/sessions.py\", line 459, in prepare_request\n",
            "    hooks=merge_hooks(request.hooks, self.hooks),\n",
            "  File \"/usr/local/lib/python3.7/dist-packages/requests/models.py\", line 314, in prepare\n",
            "    self.prepare_url(url, params)\n",
            "  File \"/usr/local/lib/python3.7/dist-packages/requests/models.py\", line 388, in prepare_url\n",
            "    raise MissingSchema(error)\n",
            "requests.exceptions.MissingSchema: Invalid URL '': No schema supplied. Perhaps you meant http://?\n",
            "\n",
            "2021-10-15 18:46:20.194 Traceback (most recent call last):\n",
            "  File \"/usr/local/lib/python3.7/dist-packages/streamlit/script_runner.py\", line 354, in _run_script\n",
            "    exec(code, module.__dict__)\n",
            "  File \"/content/score.py\", line 39, in <module>\n",
            "    content = requests.get(path).content #conversion of URL to byte array\n",
            "  File \"/usr/local/lib/python3.7/dist-packages/requests/api.py\", line 76, in get\n",
            "    return request('get', url, params=params, **kwargs)\n",
            "  File \"/usr/local/lib/python3.7/dist-packages/requests/api.py\", line 61, in request\n",
            "    return session.request(method=method, url=url, **kwargs)\n",
            "  File \"/usr/local/lib/python3.7/dist-packages/requests/sessions.py\", line 516, in request\n",
            "    prep = self.prepare_request(req)\n",
            "  File \"/usr/local/lib/python3.7/dist-packages/requests/sessions.py\", line 459, in prepare_request\n",
            "    hooks=merge_hooks(request.hooks, self.hooks),\n",
            "  File \"/usr/local/lib/python3.7/dist-packages/requests/models.py\", line 314, in prepare\n",
            "    self.prepare_url(url, params)\n",
            "  File \"/usr/local/lib/python3.7/dist-packages/requests/models.py\", line 388, in prepare_url\n",
            "    raise MissingSchema(error)\n",
            "requests.exceptions.MissingSchema: Invalid URL '': No schema supplied. Perhaps you meant http://?\n",
            "\n",
            "2021-10-15 18:47:29.090 Traceback (most recent call last):\n",
            "  File \"/usr/local/lib/python3.7/dist-packages/streamlit/script_runner.py\", line 354, in _run_script\n",
            "    exec(code, module.__dict__)\n",
            "  File \"/content/score.py\", line 39, in <module>\n",
            "    content = requests.get(path).content #conversion of URL to byte array\n",
            "  File \"/usr/local/lib/python3.7/dist-packages/requests/api.py\", line 76, in get\n",
            "    return request('get', url, params=params, **kwargs)\n",
            "  File \"/usr/local/lib/python3.7/dist-packages/requests/api.py\", line 61, in request\n",
            "    return session.request(method=method, url=url, **kwargs)\n",
            "  File \"/usr/local/lib/python3.7/dist-packages/requests/sessions.py\", line 516, in request\n",
            "    prep = self.prepare_request(req)\n",
            "  File \"/usr/local/lib/python3.7/dist-packages/requests/sessions.py\", line 459, in prepare_request\n",
            "    hooks=merge_hooks(request.hooks, self.hooks),\n",
            "  File \"/usr/local/lib/python3.7/dist-packages/requests/models.py\", line 314, in prepare\n",
            "    self.prepare_url(url, params)\n",
            "  File \"/usr/local/lib/python3.7/dist-packages/requests/models.py\", line 388, in prepare_url\n",
            "    raise MissingSchema(error)\n",
            "requests.exceptions.MissingSchema: Invalid URL '': No schema supplied. Perhaps you meant http://?\n",
            "\n",
            "\n",
            "  You can now view your Streamlit app in your browser.\n",
            "\n",
            "  Network URL: http://172.28.0.2:8508\n",
            "  External URL: http://34.125.81.210:8508\n",
            "\n",
            "\n",
            "  You can now view your Streamlit app in your browser.\n",
            "\n",
            "  Network URL: http://172.28.0.2:8509\n",
            "  External URL: http://34.125.81.210:8509\n",
            "\n",
            "2021-10-15 19:15:44.943590: E tensorflow/stream_executor/cuda/cuda_driver.cc:271] failed call to cuInit: CUDA_ERROR_NO_DEVICE: no CUDA-capable device is detected\n",
            "2021-10-15 19:15:44.943688: I tensorflow/stream_executor/cuda/cuda_diagnostics.cc:156] kernel driver does not appear to be running on this host (e283ac559329): /proc/driver/nvidia/version does not exist\n",
            "2021-10-15 19:15:47.925 Traceback (most recent call last):\n",
            "  File \"/usr/local/lib/python3.7/dist-packages/streamlit/script_runner.py\", line 354, in _run_script\n",
            "    exec(code, module.__dict__)\n",
            "  File \"/content/score.py\", line 57, in <module>\n",
            "    label = np.argmax(model.predict(decode_img(content)), axis=1)\n",
            "NameError: name 'content' is not defined\n",
            "\n",
            "2021-10-15 19:15:55.345 Traceback (most recent call last):\n",
            "  File \"/usr/local/lib/python3.7/dist-packages/streamlit/script_runner.py\", line 354, in _run_script\n",
            "    exec(code, module.__dict__)\n",
            "  File \"/content/score.py\", line 57, in <module>\n",
            "    label = np.argmax(model.predict(decode_img(content)), axis=1)\n",
            "NameError: name 'content' is not defined\n",
            "\n",
            "\n",
            "  You can now view your Streamlit app in your browser.\n",
            "\n",
            "  Network URL: http://172.28.0.2:8510\n",
            "  External URL: http://34.125.81.210:8510\n",
            "\n",
            "2021-10-15 19:25:38.191491: E tensorflow/stream_executor/cuda/cuda_driver.cc:271] failed call to cuInit: CUDA_ERROR_NO_DEVICE: no CUDA-capable device is detected\n",
            "2021-10-15 19:25:38.191898: I tensorflow/stream_executor/cuda/cuda_diagnostics.cc:156] kernel driver does not appear to be running on this host (e283ac559329): /proc/driver/nvidia/version does not exist\n",
            "2021-10-15 19:25:41.121 Traceback (most recent call last):\n",
            "  File \"/usr/local/lib/python3.7/dist-packages/streamlit/script_runner.py\", line 354, in _run_script\n",
            "    exec(code, module.__dict__)\n",
            "  File \"/content/score.py\", line 58, in <module>\n",
            "    label = np.argmax(model.predict(decode_img(img)), axis=1)\n",
            "NameError: name 'img' is not defined\n",
            "\n",
            "2021-10-15 19:25:44.156 Traceback (most recent call last):\n",
            "  File \"/usr/local/lib/python3.7/dist-packages/streamlit/script_runner.py\", line 354, in _run_script\n",
            "    exec(code, module.__dict__)\n",
            "  File \"/content/score.py\", line 58, in <module>\n",
            "    label = np.argmax(model.predict(decode_img(img)), axis=1)\n",
            "NameError: name 'img' is not defined\n",
            "\n",
            "\n",
            "  You can now view your Streamlit app in your browser.\n",
            "\n",
            "  Network URL: http://172.28.0.2:8511\n",
            "  External URL: http://34.125.81.210:8511\n",
            "\n",
            "2021-10-15 19:28:03.883979: E tensorflow/stream_executor/cuda/cuda_driver.cc:271] failed call to cuInit: CUDA_ERROR_NO_DEVICE: no CUDA-capable device is detected\n",
            "2021-10-15 19:28:03.884659: I tensorflow/stream_executor/cuda/cuda_diagnostics.cc:156] kernel driver does not appear to be running on this host (e283ac559329): /proc/driver/nvidia/version does not exist\n",
            "2021-10-15 19:28:07.015 Traceback (most recent call last):\n",
            "  File \"/usr/local/lib/python3.7/dist-packages/streamlit/script_runner.py\", line 354, in _run_script\n",
            "    exec(code, module.__dict__)\n",
            "  File \"/content/score.py\", line 57, in <module>\n",
            "    label = np.argmax(model.predict(decode_img(content)), axis=1)\n",
            "NameError: name 'content' is not defined\n",
            "\n",
            "2021-10-15 19:28:07.840 Traceback (most recent call last):\n",
            "  File \"/usr/local/lib/python3.7/dist-packages/streamlit/script_runner.py\", line 354, in _run_script\n",
            "    exec(code, module.__dict__)\n",
            "  File \"/content/score.py\", line 57, in <module>\n",
            "    label = np.argmax(model.predict(decode_img(content)), axis=1)\n",
            "NameError: name 'content' is not defined\n",
            "\n",
            "\n",
            "  You can now view your Streamlit app in your browser.\n",
            "\n",
            "  Network URL: http://172.28.0.2:8512\n",
            "  External URL: http://34.125.81.210:8512\n",
            "\n",
            "2021-10-15 19:38:05.533557: E tensorflow/stream_executor/cuda/cuda_driver.cc:271] failed call to cuInit: CUDA_ERROR_NO_DEVICE: no CUDA-capable device is detected\n",
            "2021-10-15 19:38:05.534990: I tensorflow/stream_executor/cuda/cuda_diagnostics.cc:156] kernel driver does not appear to be running on this host (e283ac559329): /proc/driver/nvidia/version does not exist\n",
            "2021-10-15 19:38:08.541 Traceback (most recent call last):\n",
            "  File \"/usr/local/lib/python3.7/dist-packages/streamlit/script_runner.py\", line 354, in _run_script\n",
            "    exec(code, module.__dict__)\n",
            "  File \"/content/score.py\", line 56, in <module>\n",
            "    label = np.argmax(model.predict(decode_img(uploadFile)), axis=1)\n",
            "  File \"/content/score.py\", line 33, in decode_img\n",
            "    img = tf.image.decode_jpeg(image, channels=3)\n",
            "  File \"/usr/local/lib/python3.7/dist-packages/tensorflow/python/ops/gen_image_ops.py\", line 1175, in decode_jpeg\n",
            "    name=name, ctx=_ctx)\n",
            "  File \"/usr/local/lib/python3.7/dist-packages/tensorflow/python/ops/gen_image_ops.py\", line 1239, in decode_jpeg_eager_fallback\n",
            "    contents = _ops.convert_to_tensor(contents, _dtypes.string)\n",
            "  File \"/usr/local/lib/python3.7/dist-packages/tensorflow/python/profiler/trace.py\", line 163, in wrapped\n",
            "    return func(*args, **kwargs)\n",
            "  File \"/usr/local/lib/python3.7/dist-packages/tensorflow/python/framework/ops.py\", line 1566, in convert_to_tensor\n",
            "    ret = conversion_func(value, dtype=dtype, name=name, as_ref=as_ref)\n",
            "  File \"/usr/local/lib/python3.7/dist-packages/tensorflow/python/framework/constant_op.py\", line 346, in _constant_tensor_conversion_function\n",
            "    return constant(v, dtype=dtype, name=name)\n",
            "  File \"/usr/local/lib/python3.7/dist-packages/tensorflow/python/framework/constant_op.py\", line 272, in constant\n",
            "    allow_broadcast=True)\n",
            "  File \"/usr/local/lib/python3.7/dist-packages/tensorflow/python/framework/constant_op.py\", line 283, in _constant_impl\n",
            "    return _constant_eager_impl(ctx, value, dtype, shape, verify_shape)\n",
            "  File \"/usr/local/lib/python3.7/dist-packages/tensorflow/python/framework/constant_op.py\", line 308, in _constant_eager_impl\n",
            "    t = convert_to_eager_tensor(value, ctx, dtype)\n",
            "  File \"/usr/local/lib/python3.7/dist-packages/tensorflow/python/framework/constant_op.py\", line 106, in convert_to_eager_tensor\n",
            "    return ops.EagerTensor(value, ctx.device_name, dtype)\n",
            "ValueError: Attempt to convert a value (None) with an unsupported type (<class 'NoneType'>) to a Tensor.\n",
            "\n",
            "2021-10-15 19:38:12.133 Traceback (most recent call last):\n",
            "  File \"/usr/local/lib/python3.7/dist-packages/streamlit/script_runner.py\", line 354, in _run_script\n",
            "    exec(code, module.__dict__)\n",
            "  File \"/content/score.py\", line 56, in <module>\n",
            "    label = np.argmax(model.predict(decode_img(uploadFile)), axis=1)\n",
            "  File \"/content/score.py\", line 33, in decode_img\n",
            "    img = tf.image.decode_jpeg(image, channels=3)\n",
            "  File \"/usr/local/lib/python3.7/dist-packages/tensorflow/python/ops/gen_image_ops.py\", line 1175, in decode_jpeg\n",
            "    name=name, ctx=_ctx)\n",
            "  File \"/usr/local/lib/python3.7/dist-packages/tensorflow/python/ops/gen_image_ops.py\", line 1239, in decode_jpeg_eager_fallback\n",
            "    contents = _ops.convert_to_tensor(contents, _dtypes.string)\n",
            "  File \"/usr/local/lib/python3.7/dist-packages/tensorflow/python/profiler/trace.py\", line 163, in wrapped\n",
            "    return func(*args, **kwargs)\n",
            "  File \"/usr/local/lib/python3.7/dist-packages/tensorflow/python/framework/ops.py\", line 1566, in convert_to_tensor\n",
            "    ret = conversion_func(value, dtype=dtype, name=name, as_ref=as_ref)\n",
            "  File \"/usr/local/lib/python3.7/dist-packages/tensorflow/python/framework/constant_op.py\", line 346, in _constant_tensor_conversion_function\n",
            "    return constant(v, dtype=dtype, name=name)\n",
            "  File \"/usr/local/lib/python3.7/dist-packages/tensorflow/python/framework/constant_op.py\", line 272, in constant\n",
            "    allow_broadcast=True)\n",
            "  File \"/usr/local/lib/python3.7/dist-packages/tensorflow/python/framework/constant_op.py\", line 283, in _constant_impl\n",
            "    return _constant_eager_impl(ctx, value, dtype, shape, verify_shape)\n",
            "  File \"/usr/local/lib/python3.7/dist-packages/tensorflow/python/framework/constant_op.py\", line 308, in _constant_eager_impl\n",
            "    t = convert_to_eager_tensor(value, ctx, dtype)\n",
            "  File \"/usr/local/lib/python3.7/dist-packages/tensorflow/python/framework/constant_op.py\", line 106, in convert_to_eager_tensor\n",
            "    return ops.EagerTensor(value, ctx.device_name, dtype)\n",
            "ValueError: Attempt to convert a value (None) with an unsupported type (<class 'NoneType'>) to a Tensor.\n",
            "\n",
            "\n",
            "  You can now view your Streamlit app in your browser.\n",
            "\n",
            "  Network URL: http://172.28.0.2:8513\n",
            "  External URL: http://34.125.81.210:8513\n",
            "\n",
            "2021-10-15 19:40:31.406754: E tensorflow/stream_executor/cuda/cuda_driver.cc:271] failed call to cuInit: CUDA_ERROR_NO_DEVICE: no CUDA-capable device is detected\n",
            "2021-10-15 19:40:31.408347: I tensorflow/stream_executor/cuda/cuda_diagnostics.cc:156] kernel driver does not appear to be running on this host (e283ac559329): /proc/driver/nvidia/version does not exist\n",
            "2021-10-15 19:40:34.658 Traceback (most recent call last):\n",
            "  File \"/usr/local/lib/python3.7/dist-packages/streamlit/script_runner.py\", line 354, in _run_script\n",
            "    exec(code, module.__dict__)\n",
            "  File \"/content/score.py\", line 56, in <module>\n",
            "    label = np.argmax(model.predict(decode_img(content)), axis=1)\n",
            "NameError: name 'content' is not defined\n",
            "\n",
            "2021-10-15 19:40:41.216 Traceback (most recent call last):\n",
            "  File \"/usr/local/lib/python3.7/dist-packages/streamlit/script_runner.py\", line 354, in _run_script\n",
            "    exec(code, module.__dict__)\n",
            "  File \"/content/score.py\", line 56, in <module>\n",
            "    label = np.argmax(model.predict(decode_img(content)), axis=1)\n",
            "NameError: name 'content' is not defined\n",
            "\n",
            "\n",
            "  You can now view your Streamlit app in your browser.\n",
            "\n",
            "  Network URL: http://172.28.0.2:8514\n",
            "  External URL: http://34.125.81.210:8514\n",
            "\n",
            "2021-10-15 19:42:40.033013: E tensorflow/stream_executor/cuda/cuda_driver.cc:271] failed call to cuInit: CUDA_ERROR_NO_DEVICE: no CUDA-capable device is detected\n",
            "2021-10-15 19:42:40.034267: I tensorflow/stream_executor/cuda/cuda_diagnostics.cc:156] kernel driver does not appear to be running on this host (e283ac559329): /proc/driver/nvidia/version does not exist\n",
            "2021-10-15 19:42:44.418069: I tensorflow/compiler/mlir/mlir_graph_optimization_pass.cc:185] None of the MLIR Optimization Passes are enabled (registered 2)\n",
            "\n",
            "  You can now view your Streamlit app in your browser.\n",
            "\n",
            "  Network URL: http://172.28.0.2:8515\n",
            "  External URL: http://34.125.81.210:8515\n",
            "\n",
            "2021-10-15 19:47:23.985158: E tensorflow/stream_executor/cuda/cuda_driver.cc:271] failed call to cuInit: CUDA_ERROR_NO_DEVICE: no CUDA-capable device is detected\n",
            "2021-10-15 19:47:23.985764: I tensorflow/stream_executor/cuda/cuda_diagnostics.cc:156] kernel driver does not appear to be running on this host (e283ac559329): /proc/driver/nvidia/version does not exist\n",
            "2021-10-15 19:47:27.301 Traceback (most recent call last):\n",
            "  File \"/usr/local/lib/python3.7/dist-packages/streamlit/script_runner.py\", line 354, in _run_script\n",
            "    exec(code, module.__dict__)\n",
            "  File \"/content/score.py\", line 44, in <module>\n",
            "    label = np.argmax(model.predict(decode_img(content)), axis=1)\n",
            "NameError: name 'content' is not defined\n",
            "\n",
            "2021-10-15 19:47:28.715 Traceback (most recent call last):\n",
            "  File \"/usr/local/lib/python3.7/dist-packages/streamlit/script_runner.py\", line 354, in _run_script\n",
            "    exec(code, module.__dict__)\n",
            "  File \"/content/score.py\", line 44, in <module>\n",
            "    label = np.argmax(model.predict(decode_img(content)), axis=1)\n",
            "NameError: name 'content' is not defined\n",
            "\n",
            "\n",
            "  You can now view your Streamlit app in your browser.\n",
            "\n",
            "  Network URL: http://172.28.0.2:8516\n",
            "  External URL: http://34.125.81.210:8516\n",
            "\n",
            "2021-10-15 20:06:55.731245: E tensorflow/stream_executor/cuda/cuda_driver.cc:271] failed call to cuInit: CUDA_ERROR_NO_DEVICE: no CUDA-capable device is detected\n",
            "2021-10-15 20:06:55.733120: I tensorflow/stream_executor/cuda/cuda_diagnostics.cc:156] kernel driver does not appear to be running on this host (e283ac559329): /proc/driver/nvidia/version does not exist\n",
            "2021-10-15 20:06:59.205 Traceback (most recent call last):\n",
            "  File \"/usr/local/lib/python3.7/dist-packages/streamlit/script_runner.py\", line 354, in _run_script\n",
            "    exec(code, module.__dict__)\n",
            "  File \"/content/score.py\", line 48, in <module>\n",
            "    label = np.argmax(model.predict(decode_img(img)), axis=1)\n",
            "NameError: name 'img' is not defined\n",
            "\n",
            "2021-10-15 20:07:01.050 Traceback (most recent call last):\n",
            "  File \"/usr/local/lib/python3.7/dist-packages/streamlit/script_runner.py\", line 354, in _run_script\n",
            "    exec(code, module.__dict__)\n",
            "  File \"/content/score.py\", line 48, in <module>\n",
            "    label = np.argmax(model.predict(decode_img(img)), axis=1)\n",
            "NameError: name 'img' is not defined\n",
            "\n",
            "\n",
            "  You can now view your Streamlit app in your browser.\n",
            "\n",
            "  Network URL: http://172.28.0.2:8517\n",
            "  External URL: http://34.125.81.210:8517\n",
            "\n",
            "2021-10-15 20:08:17.475821: E tensorflow/stream_executor/cuda/cuda_driver.cc:271] failed call to cuInit: CUDA_ERROR_NO_DEVICE: no CUDA-capable device is detected\n",
            "2021-10-15 20:08:17.479315: I tensorflow/stream_executor/cuda/cuda_diagnostics.cc:156] kernel driver does not appear to be running on this host (e283ac559329): /proc/driver/nvidia/version does not exist\n",
            "2021-10-15 20:08:17.775 Traceback (most recent call last):\n",
            "  File \"/usr/local/lib/python3.7/dist-packages/streamlit/script_runner.py\", line 354, in _run_script\n",
            "    exec(code, module.__dict__)\n",
            "  File \"/content/score.py\", line 48, in <module>\n",
            "    label = np.argmax(model.predict(decode_img(path)), axis=1)\n",
            "  File \"/content/score.py\", line 33, in decode_img\n",
            "    img = tf.image.decode_jpeg(image, channels=3)\n",
            "  File \"/usr/local/lib/python3.7/dist-packages/tensorflow/python/ops/gen_image_ops.py\", line 1175, in decode_jpeg\n",
            "    name=name, ctx=_ctx)\n",
            "  File \"/usr/local/lib/python3.7/dist-packages/tensorflow/python/ops/gen_image_ops.py\", line 1239, in decode_jpeg_eager_fallback\n",
            "    contents = _ops.convert_to_tensor(contents, _dtypes.string)\n",
            "  File \"/usr/local/lib/python3.7/dist-packages/tensorflow/python/profiler/trace.py\", line 163, in wrapped\n",
            "    return func(*args, **kwargs)\n",
            "  File \"/usr/local/lib/python3.7/dist-packages/tensorflow/python/framework/ops.py\", line 1566, in convert_to_tensor\n",
            "    ret = conversion_func(value, dtype=dtype, name=name, as_ref=as_ref)\n",
            "  File \"/usr/local/lib/python3.7/dist-packages/tensorflow/python/framework/constant_op.py\", line 346, in _constant_tensor_conversion_function\n",
            "    return constant(v, dtype=dtype, name=name)\n",
            "  File \"/usr/local/lib/python3.7/dist-packages/tensorflow/python/framework/constant_op.py\", line 272, in constant\n",
            "    allow_broadcast=True)\n",
            "  File \"/usr/local/lib/python3.7/dist-packages/tensorflow/python/framework/constant_op.py\", line 283, in _constant_impl\n",
            "    return _constant_eager_impl(ctx, value, dtype, shape, verify_shape)\n",
            "  File \"/usr/local/lib/python3.7/dist-packages/tensorflow/python/framework/constant_op.py\", line 308, in _constant_eager_impl\n",
            "    t = convert_to_eager_tensor(value, ctx, dtype)\n",
            "  File \"/usr/local/lib/python3.7/dist-packages/tensorflow/python/framework/constant_op.py\", line 106, in convert_to_eager_tensor\n",
            "    return ops.EagerTensor(value, ctx.device_name, dtype)\n",
            "ValueError: Attempt to convert a value (None) with an unsupported type (<class 'NoneType'>) to a Tensor.\n",
            "\n",
            "2021-10-15 20:08:21.315 Traceback (most recent call last):\n",
            "  File \"/usr/local/lib/python3.7/dist-packages/streamlit/script_runner.py\", line 354, in _run_script\n",
            "    exec(code, module.__dict__)\n",
            "  File \"/content/score.py\", line 48, in <module>\n",
            "    label = np.argmax(model.predict(decode_img(path)), axis=1)\n",
            "  File \"/content/score.py\", line 33, in decode_img\n",
            "    img = tf.image.decode_jpeg(image, channels=3)\n",
            "  File \"/usr/local/lib/python3.7/dist-packages/tensorflow/python/ops/gen_image_ops.py\", line 1175, in decode_jpeg\n",
            "    name=name, ctx=_ctx)\n",
            "  File \"/usr/local/lib/python3.7/dist-packages/tensorflow/python/ops/gen_image_ops.py\", line 1239, in decode_jpeg_eager_fallback\n",
            "    contents = _ops.convert_to_tensor(contents, _dtypes.string)\n",
            "  File \"/usr/local/lib/python3.7/dist-packages/tensorflow/python/profiler/trace.py\", line 163, in wrapped\n",
            "    return func(*args, **kwargs)\n",
            "  File \"/usr/local/lib/python3.7/dist-packages/tensorflow/python/framework/ops.py\", line 1566, in convert_to_tensor\n",
            "    ret = conversion_func(value, dtype=dtype, name=name, as_ref=as_ref)\n",
            "  File \"/usr/local/lib/python3.7/dist-packages/tensorflow/python/framework/constant_op.py\", line 346, in _constant_tensor_conversion_function\n",
            "    return constant(v, dtype=dtype, name=name)\n",
            "  File \"/usr/local/lib/python3.7/dist-packages/tensorflow/python/framework/constant_op.py\", line 272, in constant\n",
            "    allow_broadcast=True)\n",
            "  File \"/usr/local/lib/python3.7/dist-packages/tensorflow/python/framework/constant_op.py\", line 283, in _constant_impl\n",
            "    return _constant_eager_impl(ctx, value, dtype, shape, verify_shape)\n",
            "  File \"/usr/local/lib/python3.7/dist-packages/tensorflow/python/framework/constant_op.py\", line 308, in _constant_eager_impl\n",
            "    t = convert_to_eager_tensor(value, ctx, dtype)\n",
            "  File \"/usr/local/lib/python3.7/dist-packages/tensorflow/python/framework/constant_op.py\", line 106, in convert_to_eager_tensor\n",
            "    return ops.EagerTensor(value, ctx.device_name, dtype)\n",
            "ValueError: Attempt to convert a value (None) with an unsupported type (<class 'NoneType'>) to a Tensor.\n",
            "\n",
            "\n",
            "  You can now view your Streamlit app in your browser.\n",
            "\n",
            "  Network URL: http://172.28.0.2:8518\n",
            "  External URL: http://34.125.81.210:8518\n",
            "\n",
            "2021-10-15 20:10:17.640470: E tensorflow/stream_executor/cuda/cuda_driver.cc:271] failed call to cuInit: CUDA_ERROR_NO_DEVICE: no CUDA-capable device is detected\n",
            "2021-10-15 20:10:17.642564: I tensorflow/stream_executor/cuda/cuda_diagnostics.cc:156] kernel driver does not appear to be running on this host (e283ac559329): /proc/driver/nvidia/version does not exist\n",
            "2021-10-15 20:10:20.585 Traceback (most recent call last):\n",
            "  File \"/usr/local/lib/python3.7/dist-packages/streamlit/script_runner.py\", line 354, in _run_script\n",
            "    exec(code, module.__dict__)\n",
            "  File \"/content/score.py\", line 49, in <module>\n",
            "    label = np.argmax(model.predict(decode_img(image)), axis=1)\n",
            "  File \"/content/score.py\", line 33, in decode_img\n",
            "    img = tf.image.decode_jpeg(image, channels=3)\n",
            "  File \"/usr/local/lib/python3.7/dist-packages/tensorflow/python/ops/gen_image_ops.py\", line 1175, in decode_jpeg\n",
            "    name=name, ctx=_ctx)\n",
            "  File \"/usr/local/lib/python3.7/dist-packages/tensorflow/python/ops/gen_image_ops.py\", line 1239, in decode_jpeg_eager_fallback\n",
            "    contents = _ops.convert_to_tensor(contents, _dtypes.string)\n",
            "  File \"/usr/local/lib/python3.7/dist-packages/tensorflow/python/profiler/trace.py\", line 163, in wrapped\n",
            "    return func(*args, **kwargs)\n",
            "  File \"/usr/local/lib/python3.7/dist-packages/tensorflow/python/framework/ops.py\", line 1566, in convert_to_tensor\n",
            "    ret = conversion_func(value, dtype=dtype, name=name, as_ref=as_ref)\n",
            "  File \"/usr/local/lib/python3.7/dist-packages/tensorflow/python/framework/constant_op.py\", line 346, in _constant_tensor_conversion_function\n",
            "    return constant(v, dtype=dtype, name=name)\n",
            "  File \"/usr/local/lib/python3.7/dist-packages/tensorflow/python/framework/constant_op.py\", line 272, in constant\n",
            "    allow_broadcast=True)\n",
            "  File \"/usr/local/lib/python3.7/dist-packages/tensorflow/python/framework/constant_op.py\", line 283, in _constant_impl\n",
            "    return _constant_eager_impl(ctx, value, dtype, shape, verify_shape)\n",
            "  File \"/usr/local/lib/python3.7/dist-packages/tensorflow/python/framework/constant_op.py\", line 308, in _constant_eager_impl\n",
            "    t = convert_to_eager_tensor(value, ctx, dtype)\n",
            "  File \"/usr/local/lib/python3.7/dist-packages/tensorflow/python/framework/constant_op.py\", line 106, in convert_to_eager_tensor\n",
            "    return ops.EagerTensor(value, ctx.device_name, dtype)\n",
            "ValueError: Attempt to convert a value (<module 'keras_preprocessing.image' from '/usr/local/lib/python3.7/dist-packages/keras_preprocessing/image/__init__.py'>) with an unsupported type (<class 'module'>) to a Tensor.\n",
            "\n",
            "2021-10-15 20:10:21.437 Traceback (most recent call last):\n",
            "  File \"/usr/local/lib/python3.7/dist-packages/streamlit/script_runner.py\", line 354, in _run_script\n",
            "    exec(code, module.__dict__)\n",
            "  File \"/content/score.py\", line 49, in <module>\n",
            "    label = np.argmax(model.predict(decode_img(image)), axis=1)\n",
            "  File \"/content/score.py\", line 33, in decode_img\n",
            "    img = tf.image.decode_jpeg(image, channels=3)\n",
            "  File \"/usr/local/lib/python3.7/dist-packages/tensorflow/python/ops/gen_image_ops.py\", line 1175, in decode_jpeg\n",
            "    name=name, ctx=_ctx)\n",
            "  File \"/usr/local/lib/python3.7/dist-packages/tensorflow/python/ops/gen_image_ops.py\", line 1239, in decode_jpeg_eager_fallback\n",
            "    contents = _ops.convert_to_tensor(contents, _dtypes.string)\n",
            "  File \"/usr/local/lib/python3.7/dist-packages/tensorflow/python/profiler/trace.py\", line 163, in wrapped\n",
            "    return func(*args, **kwargs)\n",
            "  File \"/usr/local/lib/python3.7/dist-packages/tensorflow/python/framework/ops.py\", line 1566, in convert_to_tensor\n",
            "    ret = conversion_func(value, dtype=dtype, name=name, as_ref=as_ref)\n",
            "  File \"/usr/local/lib/python3.7/dist-packages/tensorflow/python/framework/constant_op.py\", line 346, in _constant_tensor_conversion_function\n",
            "    return constant(v, dtype=dtype, name=name)\n",
            "  File \"/usr/local/lib/python3.7/dist-packages/tensorflow/python/framework/constant_op.py\", line 272, in constant\n",
            "    allow_broadcast=True)\n",
            "  File \"/usr/local/lib/python3.7/dist-packages/tensorflow/python/framework/constant_op.py\", line 283, in _constant_impl\n",
            "    return _constant_eager_impl(ctx, value, dtype, shape, verify_shape)\n",
            "  File \"/usr/local/lib/python3.7/dist-packages/tensorflow/python/framework/constant_op.py\", line 308, in _constant_eager_impl\n",
            "    t = convert_to_eager_tensor(value, ctx, dtype)\n",
            "  File \"/usr/local/lib/python3.7/dist-packages/tensorflow/python/framework/constant_op.py\", line 106, in convert_to_eager_tensor\n",
            "    return ops.EagerTensor(value, ctx.device_name, dtype)\n",
            "ValueError: Attempt to convert a value (<module 'keras_preprocessing.image' from '/usr/local/lib/python3.7/dist-packages/keras_preprocessing/image/__init__.py'>) with an unsupported type (<class 'module'>) to a Tensor.\n",
            "\n",
            "\n",
            "  You can now view your Streamlit app in your browser.\n",
            "\n",
            "  Network URL: http://172.28.0.2:8519\n",
            "  External URL: http://34.125.81.210:8519\n",
            "\n",
            "2021-10-15 20:11:02.055636: E tensorflow/stream_executor/cuda/cuda_driver.cc:271] failed call to cuInit: CUDA_ERROR_NO_DEVICE: no CUDA-capable device is detected\n",
            "2021-10-15 20:11:02.056287: I tensorflow/stream_executor/cuda/cuda_diagnostics.cc:156] kernel driver does not appear to be running on this host (e283ac559329): /proc/driver/nvidia/version does not exist\n",
            "2021-10-15 20:11:05.793 Traceback (most recent call last):\n",
            "  File \"/usr/local/lib/python3.7/dist-packages/streamlit/script_runner.py\", line 354, in _run_script\n",
            "    exec(code, module.__dict__)\n",
            "  File \"/content/score.py\", line 49, in <module>\n",
            "    label = np.argmax(model.predict(decode_img(image)), axis=1)\n",
            "  File \"/content/score.py\", line 33, in decode_img\n",
            "    img = tf.image.decode_jpeg(image, channels=3)\n",
            "  File \"/usr/local/lib/python3.7/dist-packages/tensorflow/python/ops/gen_image_ops.py\", line 1175, in decode_jpeg\n",
            "    name=name, ctx=_ctx)\n",
            "  File \"/usr/local/lib/python3.7/dist-packages/tensorflow/python/ops/gen_image_ops.py\", line 1239, in decode_jpeg_eager_fallback\n",
            "    contents = _ops.convert_to_tensor(contents, _dtypes.string)\n",
            "  File \"/usr/local/lib/python3.7/dist-packages/tensorflow/python/profiler/trace.py\", line 163, in wrapped\n",
            "    return func(*args, **kwargs)\n",
            "  File \"/usr/local/lib/python3.7/dist-packages/tensorflow/python/framework/ops.py\", line 1566, in convert_to_tensor\n",
            "    ret = conversion_func(value, dtype=dtype, name=name, as_ref=as_ref)\n",
            "  File \"/usr/local/lib/python3.7/dist-packages/tensorflow/python/framework/constant_op.py\", line 346, in _constant_tensor_conversion_function\n",
            "    return constant(v, dtype=dtype, name=name)\n",
            "  File \"/usr/local/lib/python3.7/dist-packages/tensorflow/python/framework/constant_op.py\", line 272, in constant\n",
            "    allow_broadcast=True)\n",
            "  File \"/usr/local/lib/python3.7/dist-packages/tensorflow/python/framework/constant_op.py\", line 283, in _constant_impl\n",
            "    return _constant_eager_impl(ctx, value, dtype, shape, verify_shape)\n",
            "  File \"/usr/local/lib/python3.7/dist-packages/tensorflow/python/framework/constant_op.py\", line 308, in _constant_eager_impl\n",
            "    t = convert_to_eager_tensor(value, ctx, dtype)\n",
            "  File \"/usr/local/lib/python3.7/dist-packages/tensorflow/python/framework/constant_op.py\", line 106, in convert_to_eager_tensor\n",
            "    return ops.EagerTensor(value, ctx.device_name, dtype)\n",
            "ValueError: Attempt to convert a value (<module 'keras_preprocessing.image' from '/usr/local/lib/python3.7/dist-packages/keras_preprocessing/image/__init__.py'>) with an unsupported type (<class 'module'>) to a Tensor.\n",
            "\n",
            "2021-10-15 20:11:06.246 Traceback (most recent call last):\n",
            "  File \"/usr/local/lib/python3.7/dist-packages/streamlit/script_runner.py\", line 354, in _run_script\n",
            "    exec(code, module.__dict__)\n",
            "  File \"/content/score.py\", line 49, in <module>\n",
            "    label = np.argmax(model.predict(decode_img(image)), axis=1)\n",
            "  File \"/content/score.py\", line 33, in decode_img\n",
            "    img = tf.image.decode_jpeg(image, channels=3)\n",
            "  File \"/usr/local/lib/python3.7/dist-packages/tensorflow/python/ops/gen_image_ops.py\", line 1175, in decode_jpeg\n",
            "    name=name, ctx=_ctx)\n",
            "  File \"/usr/local/lib/python3.7/dist-packages/tensorflow/python/ops/gen_image_ops.py\", line 1239, in decode_jpeg_eager_fallback\n",
            "    contents = _ops.convert_to_tensor(contents, _dtypes.string)\n",
            "  File \"/usr/local/lib/python3.7/dist-packages/tensorflow/python/profiler/trace.py\", line 163, in wrapped\n",
            "    return func(*args, **kwargs)\n",
            "  File \"/usr/local/lib/python3.7/dist-packages/tensorflow/python/framework/ops.py\", line 1566, in convert_to_tensor\n",
            "    ret = conversion_func(value, dtype=dtype, name=name, as_ref=as_ref)\n",
            "  File \"/usr/local/lib/python3.7/dist-packages/tensorflow/python/framework/constant_op.py\", line 346, in _constant_tensor_conversion_function\n",
            "    return constant(v, dtype=dtype, name=name)\n",
            "  File \"/usr/local/lib/python3.7/dist-packages/tensorflow/python/framework/constant_op.py\", line 272, in constant\n",
            "    allow_broadcast=True)\n",
            "  File \"/usr/local/lib/python3.7/dist-packages/tensorflow/python/framework/constant_op.py\", line 283, in _constant_impl\n",
            "    return _constant_eager_impl(ctx, value, dtype, shape, verify_shape)\n",
            "  File \"/usr/local/lib/python3.7/dist-packages/tensorflow/python/framework/constant_op.py\", line 308, in _constant_eager_impl\n",
            "    t = convert_to_eager_tensor(value, ctx, dtype)\n",
            "  File \"/usr/local/lib/python3.7/dist-packages/tensorflow/python/framework/constant_op.py\", line 106, in convert_to_eager_tensor\n",
            "    return ops.EagerTensor(value, ctx.device_name, dtype)\n",
            "ValueError: Attempt to convert a value (<module 'keras_preprocessing.image' from '/usr/local/lib/python3.7/dist-packages/keras_preprocessing/image/__init__.py'>) with an unsupported type (<class 'module'>) to a Tensor.\n",
            "\n",
            "\n",
            "  You can now view your Streamlit app in your browser.\n",
            "\n",
            "  Network URL: http://172.28.0.2:8520\n",
            "  External URL: http://34.125.81.210:8520\n",
            "\n",
            "2021-10-15 20:13:40.993556: E tensorflow/stream_executor/cuda/cuda_driver.cc:271] failed call to cuInit: CUDA_ERROR_NO_DEVICE: no CUDA-capable device is detected\n",
            "2021-10-15 20:13:40.999593: I tensorflow/stream_executor/cuda/cuda_diagnostics.cc:156] kernel driver does not appear to be running on this host (e283ac559329): /proc/driver/nvidia/version does not exist\n",
            "2021-10-15 20:13:42.120 Traceback (most recent call last):\n",
            "  File \"/usr/local/lib/python3.7/dist-packages/streamlit/script_runner.py\", line 354, in _run_script\n",
            "    exec(code, module.__dict__)\n",
            "  File \"/content/score.py\", line 48, in <module>\n",
            "    image = np.array(img)\n",
            "NameError: name 'img' is not defined\n",
            "\n",
            "2021-10-15 20:13:44.831 Traceback (most recent call last):\n",
            "  File \"/usr/local/lib/python3.7/dist-packages/streamlit/script_runner.py\", line 354, in _run_script\n",
            "    exec(code, module.__dict__)\n",
            "  File \"/content/score.py\", line 48, in <module>\n",
            "    image = np.array(img)\n",
            "NameError: name 'img' is not defined\n",
            "\n",
            "\n",
            "  You can now view your Streamlit app in your browser.\n",
            "\n",
            "  Network URL: http://172.28.0.2:8521\n",
            "  External URL: http://34.125.81.210:8521\n",
            "\n",
            "2021-10-15 20:20:00.405750: E tensorflow/stream_executor/cuda/cuda_driver.cc:271] failed call to cuInit: CUDA_ERROR_NO_DEVICE: no CUDA-capable device is detected\n",
            "2021-10-15 20:20:00.406537: I tensorflow/stream_executor/cuda/cuda_diagnostics.cc:156] kernel driver does not appear to be running on this host (e283ac559329): /proc/driver/nvidia/version does not exist\n",
            "2021-10-15 20:20:02.584 Traceback (most recent call last):\n",
            "  File \"/usr/local/lib/python3.7/dist-packages/streamlit/script_runner.py\", line 354, in _run_script\n",
            "    exec(code, module.__dict__)\n",
            "  File \"/content/score.py\", line 49, in <module>\n",
            "    label = np.argmax(model.predict(decode_img(image)), axis=1)\n",
            "  File \"/content/score.py\", line 33, in decode_img\n",
            "    img1 = tf.image.decode_jpeg(image, channels=3)\n",
            "  File \"/usr/local/lib/python3.7/dist-packages/tensorflow/python/ops/gen_image_ops.py\", line 1175, in decode_jpeg\n",
            "    name=name, ctx=_ctx)\n",
            "  File \"/usr/local/lib/python3.7/dist-packages/tensorflow/python/ops/gen_image_ops.py\", line 1239, in decode_jpeg_eager_fallback\n",
            "    contents = _ops.convert_to_tensor(contents, _dtypes.string)\n",
            "  File \"/usr/local/lib/python3.7/dist-packages/tensorflow/python/profiler/trace.py\", line 163, in wrapped\n",
            "    return func(*args, **kwargs)\n",
            "  File \"/usr/local/lib/python3.7/dist-packages/tensorflow/python/framework/ops.py\", line 1566, in convert_to_tensor\n",
            "    ret = conversion_func(value, dtype=dtype, name=name, as_ref=as_ref)\n",
            "  File \"/usr/local/lib/python3.7/dist-packages/tensorflow/python/framework/constant_op.py\", line 346, in _constant_tensor_conversion_function\n",
            "    return constant(v, dtype=dtype, name=name)\n",
            "  File \"/usr/local/lib/python3.7/dist-packages/tensorflow/python/framework/constant_op.py\", line 272, in constant\n",
            "    allow_broadcast=True)\n",
            "  File \"/usr/local/lib/python3.7/dist-packages/tensorflow/python/framework/constant_op.py\", line 283, in _constant_impl\n",
            "    return _constant_eager_impl(ctx, value, dtype, shape, verify_shape)\n",
            "  File \"/usr/local/lib/python3.7/dist-packages/tensorflow/python/framework/constant_op.py\", line 308, in _constant_eager_impl\n",
            "    t = convert_to_eager_tensor(value, ctx, dtype)\n",
            "  File \"/usr/local/lib/python3.7/dist-packages/tensorflow/python/framework/constant_op.py\", line 106, in convert_to_eager_tensor\n",
            "    return ops.EagerTensor(value, ctx.device_name, dtype)\n",
            "ValueError: Attempt to convert a value (<module 'keras_preprocessing.image' from '/usr/local/lib/python3.7/dist-packages/keras_preprocessing/image/__init__.py'>) with an unsupported type (<class 'module'>) to a Tensor.\n",
            "\n",
            "2021-10-15 20:20:04.849 Traceback (most recent call last):\n",
            "  File \"/usr/local/lib/python3.7/dist-packages/streamlit/script_runner.py\", line 354, in _run_script\n",
            "    exec(code, module.__dict__)\n",
            "  File \"/content/score.py\", line 49, in <module>\n",
            "    label = np.argmax(model.predict(decode_img(image)), axis=1)\n",
            "  File \"/content/score.py\", line 33, in decode_img\n",
            "    img1 = tf.image.decode_jpeg(image, channels=3)\n",
            "  File \"/usr/local/lib/python3.7/dist-packages/tensorflow/python/ops/gen_image_ops.py\", line 1175, in decode_jpeg\n",
            "    name=name, ctx=_ctx)\n",
            "  File \"/usr/local/lib/python3.7/dist-packages/tensorflow/python/ops/gen_image_ops.py\", line 1239, in decode_jpeg_eager_fallback\n",
            "    contents = _ops.convert_to_tensor(contents, _dtypes.string)\n",
            "  File \"/usr/local/lib/python3.7/dist-packages/tensorflow/python/profiler/trace.py\", line 163, in wrapped\n",
            "    return func(*args, **kwargs)\n",
            "  File \"/usr/local/lib/python3.7/dist-packages/tensorflow/python/framework/ops.py\", line 1566, in convert_to_tensor\n",
            "    ret = conversion_func(value, dtype=dtype, name=name, as_ref=as_ref)\n",
            "  File \"/usr/local/lib/python3.7/dist-packages/tensorflow/python/framework/constant_op.py\", line 346, in _constant_tensor_conversion_function\n",
            "    return constant(v, dtype=dtype, name=name)\n",
            "  File \"/usr/local/lib/python3.7/dist-packages/tensorflow/python/framework/constant_op.py\", line 272, in constant\n",
            "    allow_broadcast=True)\n",
            "  File \"/usr/local/lib/python3.7/dist-packages/tensorflow/python/framework/constant_op.py\", line 283, in _constant_impl\n",
            "    return _constant_eager_impl(ctx, value, dtype, shape, verify_shape)\n",
            "  File \"/usr/local/lib/python3.7/dist-packages/tensorflow/python/framework/constant_op.py\", line 308, in _constant_eager_impl\n",
            "    t = convert_to_eager_tensor(value, ctx, dtype)\n",
            "  File \"/usr/local/lib/python3.7/dist-packages/tensorflow/python/framework/constant_op.py\", line 106, in convert_to_eager_tensor\n",
            "    return ops.EagerTensor(value, ctx.device_name, dtype)\n",
            "ValueError: Attempt to convert a value (<module 'keras_preprocessing.image' from '/usr/local/lib/python3.7/dist-packages/keras_preprocessing/image/__init__.py'>) with an unsupported type (<class 'module'>) to a Tensor.\n",
            "\n",
            "2021-10-15 20:22:27.604 Traceback (most recent call last):\n",
            "  File \"/usr/local/lib/python3.7/dist-packages/streamlit/script_runner.py\", line 354, in _run_script\n",
            "    exec(code, module.__dict__)\n",
            "  File \"/content/score.py\", line 49, in <module>\n",
            "    label = np.argmax(model.predict(decode_img(image)), axis=1)\n",
            "  File \"/content/score.py\", line 33, in decode_img\n",
            "    img1 = tf.image.decode_jpeg(image, channels=3)\n",
            "  File \"/usr/local/lib/python3.7/dist-packages/tensorflow/python/ops/gen_image_ops.py\", line 1175, in decode_jpeg\n",
            "    name=name, ctx=_ctx)\n",
            "  File \"/usr/local/lib/python3.7/dist-packages/tensorflow/python/ops/gen_image_ops.py\", line 1239, in decode_jpeg_eager_fallback\n",
            "    contents = _ops.convert_to_tensor(contents, _dtypes.string)\n",
            "  File \"/usr/local/lib/python3.7/dist-packages/tensorflow/python/profiler/trace.py\", line 163, in wrapped\n",
            "    return func(*args, **kwargs)\n",
            "  File \"/usr/local/lib/python3.7/dist-packages/tensorflow/python/framework/ops.py\", line 1566, in convert_to_tensor\n",
            "    ret = conversion_func(value, dtype=dtype, name=name, as_ref=as_ref)\n",
            "  File \"/usr/local/lib/python3.7/dist-packages/tensorflow/python/framework/tensor_conversion_registry.py\", line 52, in _default_conversion_function\n",
            "    return constant_op.constant(value, dtype, name=name)\n",
            "  File \"/usr/local/lib/python3.7/dist-packages/tensorflow/python/framework/constant_op.py\", line 272, in constant\n",
            "    allow_broadcast=True)\n",
            "  File \"/usr/local/lib/python3.7/dist-packages/tensorflow/python/framework/constant_op.py\", line 283, in _constant_impl\n",
            "    return _constant_eager_impl(ctx, value, dtype, shape, verify_shape)\n",
            "  File \"/usr/local/lib/python3.7/dist-packages/tensorflow/python/framework/constant_op.py\", line 308, in _constant_eager_impl\n",
            "    t = convert_to_eager_tensor(value, ctx, dtype)\n",
            "  File \"/usr/local/lib/python3.7/dist-packages/tensorflow/python/framework/constant_op.py\", line 106, in convert_to_eager_tensor\n",
            "    return ops.EagerTensor(value, ctx.device_name, dtype)\n",
            "ValueError: Failed to convert a NumPy array to a Tensor (Unsupported object type int).\n",
            "\n",
            "\n",
            "  You can now view your Streamlit app in your browser.\n",
            "\n",
            "  Network URL: http://172.28.0.2:8522\n",
            "  External URL: http://34.125.81.210:8522\n",
            "\n",
            "2021-10-15 20:26:41.975198: E tensorflow/stream_executor/cuda/cuda_driver.cc:271] failed call to cuInit: CUDA_ERROR_NO_DEVICE: no CUDA-capable device is detected\n",
            "2021-10-15 20:26:41.982345: I tensorflow/stream_executor/cuda/cuda_diagnostics.cc:156] kernel driver does not appear to be running on this host (e283ac559329): /proc/driver/nvidia/version does not exist\n",
            "2021-10-15 20:26:44.309 Traceback (most recent call last):\n",
            "  File \"/usr/local/lib/python3.7/dist-packages/streamlit/script_runner.py\", line 354, in _run_script\n",
            "    exec(code, module.__dict__)\n",
            "  File \"/content/score.py\", line 49, in <module>\n",
            "    tensor = tf.convert_to_tensor(image)\n",
            "  File \"/usr/local/lib/python3.7/dist-packages/tensorflow/python/util/dispatch.py\", line 206, in wrapper\n",
            "    return target(*args, **kwargs)\n",
            "  File \"/usr/local/lib/python3.7/dist-packages/tensorflow/python/framework/ops.py\", line 1431, in convert_to_tensor_v2_with_dispatch\n",
            "    value, dtype=dtype, dtype_hint=dtype_hint, name=name)\n",
            "  File \"/usr/local/lib/python3.7/dist-packages/tensorflow/python/framework/ops.py\", line 1441, in convert_to_tensor_v2\n",
            "    as_ref=False)\n",
            "  File \"/usr/local/lib/python3.7/dist-packages/tensorflow/python/profiler/trace.py\", line 163, in wrapped\n",
            "    return func(*args, **kwargs)\n",
            "  File \"/usr/local/lib/python3.7/dist-packages/tensorflow/python/framework/ops.py\", line 1566, in convert_to_tensor\n",
            "    ret = conversion_func(value, dtype=dtype, name=name, as_ref=as_ref)\n",
            "  File \"/usr/local/lib/python3.7/dist-packages/tensorflow/python/framework/constant_op.py\", line 346, in _constant_tensor_conversion_function\n",
            "    return constant(v, dtype=dtype, name=name)\n",
            "  File \"/usr/local/lib/python3.7/dist-packages/tensorflow/python/framework/constant_op.py\", line 272, in constant\n",
            "    allow_broadcast=True)\n",
            "  File \"/usr/local/lib/python3.7/dist-packages/tensorflow/python/framework/constant_op.py\", line 283, in _constant_impl\n",
            "    return _constant_eager_impl(ctx, value, dtype, shape, verify_shape)\n",
            "  File \"/usr/local/lib/python3.7/dist-packages/tensorflow/python/framework/constant_op.py\", line 308, in _constant_eager_impl\n",
            "    t = convert_to_eager_tensor(value, ctx, dtype)\n",
            "  File \"/usr/local/lib/python3.7/dist-packages/tensorflow/python/framework/constant_op.py\", line 106, in convert_to_eager_tensor\n",
            "    return ops.EagerTensor(value, ctx.device_name, dtype)\n",
            "ValueError: Attempt to convert a value (<module 'keras_preprocessing.image' from '/usr/local/lib/python3.7/dist-packages/keras_preprocessing/image/__init__.py'>) with an unsupported type (<class 'module'>) to a Tensor.\n",
            "\n",
            "2021-10-15 20:26:46.681 Traceback (most recent call last):\n",
            "  File \"/usr/local/lib/python3.7/dist-packages/streamlit/script_runner.py\", line 354, in _run_script\n",
            "    exec(code, module.__dict__)\n",
            "  File \"/content/score.py\", line 49, in <module>\n",
            "    tensor = tf.convert_to_tensor(image)\n",
            "  File \"/usr/local/lib/python3.7/dist-packages/tensorflow/python/util/dispatch.py\", line 206, in wrapper\n",
            "    return target(*args, **kwargs)\n",
            "  File \"/usr/local/lib/python3.7/dist-packages/tensorflow/python/framework/ops.py\", line 1431, in convert_to_tensor_v2_with_dispatch\n",
            "    value, dtype=dtype, dtype_hint=dtype_hint, name=name)\n",
            "  File \"/usr/local/lib/python3.7/dist-packages/tensorflow/python/framework/ops.py\", line 1441, in convert_to_tensor_v2\n",
            "    as_ref=False)\n",
            "  File \"/usr/local/lib/python3.7/dist-packages/tensorflow/python/profiler/trace.py\", line 163, in wrapped\n",
            "    return func(*args, **kwargs)\n",
            "  File \"/usr/local/lib/python3.7/dist-packages/tensorflow/python/framework/ops.py\", line 1566, in convert_to_tensor\n",
            "    ret = conversion_func(value, dtype=dtype, name=name, as_ref=as_ref)\n",
            "  File \"/usr/local/lib/python3.7/dist-packages/tensorflow/python/framework/constant_op.py\", line 346, in _constant_tensor_conversion_function\n",
            "    return constant(v, dtype=dtype, name=name)\n",
            "  File \"/usr/local/lib/python3.7/dist-packages/tensorflow/python/framework/constant_op.py\", line 272, in constant\n",
            "    allow_broadcast=True)\n",
            "  File \"/usr/local/lib/python3.7/dist-packages/tensorflow/python/framework/constant_op.py\", line 283, in _constant_impl\n",
            "    return _constant_eager_impl(ctx, value, dtype, shape, verify_shape)\n",
            "  File \"/usr/local/lib/python3.7/dist-packages/tensorflow/python/framework/constant_op.py\", line 308, in _constant_eager_impl\n",
            "    t = convert_to_eager_tensor(value, ctx, dtype)\n",
            "  File \"/usr/local/lib/python3.7/dist-packages/tensorflow/python/framework/constant_op.py\", line 106, in convert_to_eager_tensor\n",
            "    return ops.EagerTensor(value, ctx.device_name, dtype)\n",
            "ValueError: Attempt to convert a value (<module 'keras_preprocessing.image' from '/usr/local/lib/python3.7/dist-packages/keras_preprocessing/image/__init__.py'>) with an unsupported type (<class 'module'>) to a Tensor.\n",
            "\n",
            "\n",
            "  You can now view your Streamlit app in your browser.\n",
            "\n",
            "  Network URL: http://172.28.0.2:8523\n",
            "  External URL: http://34.125.81.210:8523\n",
            "\n"
          ]
        }
      ]
    }
  ]
}